
 2021-03-26 19:38:27.917798 : HTTPSConnectionPool(host='www.oxfordlearnersdictionaries.com', port=443): Max retries exceeded with url: /definition/english/entrepreneurs (Caused by ProxyError('Cannot connect to proxy.', timeout('timed out'))) at 278 - check_search - /Users/truongthuan/Develop/python/blog/flashcard/search.py
 2021-03-26 19:38:28.590045 : HTTPSConnectionPool(host='www.oxfordlearnersdictionaries.com', port=443): Max retries exceeded with url: /definition/english/entrepreneurs (Caused by ProxyError('Cannot connect to proxy.', OSError('Tunnel connection failed: 500 Internal Server Error'))) at 278 - check_search - /Users/truongthuan/Develop/python/blog/flashcard/search.py
 2021-03-26 19:38:32.438530 : HTTPSConnectionPool(host='www.oxfordlearnersdictionaries.com', port=443): Max retries exceeded with url: /definition/english/entrepreneurs (Caused by SSLError(SSLCertVerificationError(1, '[SSL: CERTIFICATE_VERIFY_FAILED] certificate verify failed: self signed certificate in certificate chain (_ssl.c:1123)'))) at 278 - check_search - /Users/truongthuan/Develop/python/blog/flashcard/search.py
 2021-03-26 19:38:33.881826 : list index out of range at 278 - check_search - /Users/truongthuan/Develop/python/blog/flashcard/search.py
 2021-03-26 19:38:41.284097 : HTTPSConnectionPool(host='www.oxfordlearnersdictionaries.com', port=443): Max retries exceeded with url: /definition/english/entrepreneurs (Caused by ProxyError('Cannot connect to proxy.', timeout('timed out'))) at 278 - check_search - /Users/truongthuan/Develop/python/blog/flashcard/search.py
 2021-03-26 19:38:45.896248 : HTTPSConnectionPool(host='www.oxfordlearnersdictionaries.com', port=443): Max retries exceeded with url: /definition/english/entrepreneurs (Caused by ProxyError('Cannot connect to proxy.', OSError('Tunnel connection failed: 503 Service Unavailable'))) at 278 - check_search - /Users/truongthuan/Develop/python/blog/flashcard/search.py
 2021-03-26 19:38:46.316988 : HTTPSConnectionPool(host='www.oxfordlearnersdictionaries.com', port=443): Max retries exceeded with url: /definition/english/entrepreneurs (Caused by ProxyError('Cannot connect to proxy.', OSError('Tunnel connection failed: 500 Internal Server Error'))) at 278 - check_search - /Users/truongthuan/Develop/python/blog/flashcard/search.py
 2021-03-26 19:38:53.328325 : HTTPSConnectionPool(host='www.oxfordlearnersdictionaries.com', port=443): Max retries exceeded with url: /definition/english/entrepreneurs (Caused by ConnectTimeoutError(<urllib3.connection.HTTPSConnection object at 0x106937dc0>, 'Connection to 178.112.5.135 timed out. (connect timeout=7)')) at 278 - check_search - /Users/truongthuan/Develop/python/blog/flashcard/search.py
 2021-03-26 19:38:57.263419 : HTTPSConnectionPool(host='www.oxfordlearnersdictionaries.com', port=443): Max retries exceeded with url: /definition/english/entrepreneurs (Caused by SSLError(SSLCertVerificationError(1, '[SSL: CERTIFICATE_VERIFY_FAILED] certificate verify failed: self signed certificate in certificate chain (_ssl.c:1123)'))) at 278 - check_search - /Users/truongthuan/Develop/python/blog/flashcard/search.py
 2021-03-26 19:38:58.183026 : HTTPSConnectionPool(host='www.oxfordlearnersdictionaries.com', port=443): Max retries exceeded with url: /definition/english/entrepreneurs (Caused by ProxyError('Cannot connect to proxy.', NewConnectionError('<urllib3.connection.HTTPSConnection object at 0x106ab5a90>: Failed to establish a new connection: [Errno 61] Connection refused'))) at 278 - check_search - /Users/truongthuan/Develop/python/blog/flashcard/search.py
 2021-03-26 19:38:58.695856 : HTTPSConnectionPool(host='www.oxfordlearnersdictionaries.com', port=443): Max retries exceeded with url: /definition/english/entrepreneurs (Caused by ProxyError('Cannot connect to proxy.', OSError('Tunnel connection failed: 503 Too many open connections'))) at 278 - check_search - /Users/truongthuan/Develop/python/blog/flashcard/search.py
 2021-03-26 19:39:01.100588 : list index out of range at 278 - check_search - /Users/truongthuan/Develop/python/blog/flashcard/search.py
 2021-03-26 19:39:01.130092 : HTTPSConnectionPool(host='www.oxfordlearnersdictionaries.com', port=443): Max retries exceeded with url: /definition/english/entrepreneurs (Caused by ProxyError('Cannot connect to proxy.', NewConnectionError('<urllib3.connection.HTTPSConnection object at 0x106b30340>: Failed to establish a new connection: [Errno 61] Connection refused'))) at 278 - check_search - /Users/truongthuan/Develop/python/blog/flashcard/search.py
 2021-03-26 19:39:02.278678 : HTTPSConnectionPool(host='www.oxfordlearnersdictionaries.com', port=443): Max retries exceeded with url: /definition/english/entrepreneurs (Caused by ProxyError('Cannot connect to proxy.', OSError('Tunnel connection failed: 503 Too many open connections'))) at 278 - check_search - /Users/truongthuan/Develop/python/blog/flashcard/search.py
 2021-03-26 19:39:02.278978 : Break search <<Entrepreneurs>> at 278 - check_search - /Users/truongthuan/Develop/python/blog/flashcard/search.py
 2021-03-26 19:39:46.925956 : HTTPSConnectionPool(host='www.oxfordlearnersdictionaries.com', port=443): Max retries exceeded with url: /definition/english/entrepreneur (Caused by ProxyError('Cannot connect to proxy.', NewConnectionError('<urllib3.connection.HTTPSConnection object at 0x103484e80>: Failed to establish a new connection: [Errno 61] Connection refused'))) at 278 - check_search - /Users/truongthuan/Develop/python/blog/flashcard/search.py
 2021-03-26 19:39:53.937142 : HTTPSConnectionPool(host='www.oxfordlearnersdictionaries.com', port=443): Max retries exceeded with url: /definition/english/entrepreneur (Caused by ConnectTimeoutError(<urllib3.connection.HTTPSConnection object at 0x1034ae610>, 'Connection to 191.242.178.209 timed out. (connect timeout=7)')) at 278 - check_search - /Users/truongthuan/Develop/python/blog/flashcard/search.py
 2021-03-26 19:44:39.185029 : HTTPSConnectionPool(host='www.oxfordlearnersdictionaries.com', port=443): Max retries exceeded with url: /definition/english/entrepreneur (Caused by ConnectTimeoutError(<urllib3.connection.HTTPSConnection object at 0x108637df0>, 'Connection to 149.125.150.250 timed out. (connect timeout=7)')) at 278 - check_search - /Users/truongthuan/Develop/python/blog/flashcard/search.py
 2021-03-26 19:45:43.971629 : HTTPSConnectionPool(host='www.oxfordlearnersdictionaries.com', port=443): Max retries exceeded with url: /definition/english/entrepreneur (Caused by ConnectTimeoutError(<urllib3.connection.HTTPSConnection object at 0x10a873ee0>, 'Connection to 45.231.75.35 timed out. (connect timeout=7)')) at 277 - check_search - /Users/truongthuan/Develop/python/blog/flashcard/search.py
 2021-03-26 19:45:44.411914 : HTTPSConnectionPool(host='www.oxfordlearnersdictionaries.com', port=443): Max retries exceeded with url: /definition/english/entrepreneur (Caused by ProxyError('Cannot connect to proxy.', NewConnectionError('<urllib3.connection.HTTPSConnection object at 0x10a89c670>: Failed to establish a new connection: [Errno 61] Connection refused'))) at 277 - check_search - /Users/truongthuan/Develop/python/blog/flashcard/search.py
 2021-03-26 19:45:44.440301 : HTTPSConnectionPool(host='www.oxfordlearnersdictionaries.com', port=443): Max retries exceeded with url: /definition/english/entrepreneur (Caused by ProxyError('Cannot connect to proxy.', NewConnectionError('<urllib3.connection.HTTPSConnection object at 0x10a89ce80>: Failed to establish a new connection: [Errno 61] Connection refused'))) at 277 - check_search - /Users/truongthuan/Develop/python/blog/flashcard/search.py
 2021-03-26 19:45:45.115789 : HTTPSConnectionPool(host='www.oxfordlearnersdictionaries.com', port=443): Max retries exceeded with url: /definition/english/entrepreneur (Caused by ProxyError('Cannot connect to proxy.', OSError('Tunnel connection failed: 500 Internal Server Error'))) at 277 - check_search - /Users/truongthuan/Develop/python/blog/flashcard/search.py
 2021-03-26 19:45:52.123395 : HTTPSConnectionPool(host='www.oxfordlearnersdictionaries.com', port=443): Max retries exceeded with url: /definition/english/entrepreneur (Caused by ConnectTimeoutError(<urllib3.connection.HTTPSConnection object at 0x10a873790>, 'Connection to 178.192.251.188 timed out. (connect timeout=7)')) at 277 - check_search - /Users/truongthuan/Develop/python/blog/flashcard/search.py
 2021-03-26 19:45:52.501405 : HTTPSConnectionPool(host='www.oxfordlearnersdictionaries.com', port=443): Max retries exceeded with url: /definition/english/entrepreneur (Caused by ProxyError('Cannot connect to proxy.', NewConnectionError('<urllib3.connection.HTTPSConnection object at 0x10a89e670>: Failed to establish a new connection: [Errno 61] Connection refused'))) at 277 - check_search - /Users/truongthuan/Develop/python/blog/flashcard/search.py
 2021-03-26 19:45:58.685505 : HTTPSConnectionPool(host='www.oxfordlearnersdictionaries.com', port=443): Max retries exceeded with url: /definition/english/entrepreneur (Caused by ProxyError('Cannot connect to proxy.', RemoteDisconnected('Remote end closed connection without response'))) at 277 - check_search - /Users/truongthuan/Develop/python/blog/flashcard/search.py
 2021-03-26 19:46:05.699324 : HTTPSConnectionPool(host='www.oxfordlearnersdictionaries.com', port=443): Max retries exceeded with url: /definition/english/entrepreneur (Caused by ConnectTimeoutError(<urllib3.connection.HTTPSConnection object at 0x10a89ee80>, 'Connection to 191.242.178.209 timed out. (connect timeout=7)')) at 277 - check_search - /Users/truongthuan/Develop/python/blog/flashcard/search.py
 2021-03-26 19:46:12.709095 : HTTPSConnectionPool(host='www.oxfordlearnersdictionaries.com', port=443): Max retries exceeded with url: /definition/english/entrepreneur (Caused by ConnectTimeoutError(<urllib3.connection.HTTPSConnection object at 0x10a8a16d0>, 'Connection to 208.80.28.208 timed out. (connect timeout=7)')) at 277 - check_search - /Users/truongthuan/Develop/python/blog/flashcard/search.py
 2021-03-26 19:46:22.507955 : saved file entrepreneur+noun+us.mp3 at 56 - downloadFileFromUrl - /Users/truongthuan/Develop/python/blog/flashcard/helper.py
 2021-03-26 19:46:40.164744 : error: HTTPSConnectionPool(host='www.oxfordlearnersdictionaries.com', port=443): Max retries exceeded with url: /media/english/uk_pron/e/ent/entre/entrepreneur__gb_1.mp3 (Caused by ProxyError('Cannot connect to proxy.', timeout('_ssl.c:1106: The handshake operation timed out'))) at 56 - downloadFileFromUrl - /Users/truongthuan/Develop/python/blog/flashcard/helper.py
 2021-03-26 19:47:01.730683 : error: HTTPSConnectionPool(host='www.oxfordlearnersdictionaries.com', port=443): Max retries exceeded with url: /media/english/uk_pron/e/ent/entre/entrepreneur__gb_1.mp3 (Caused by ProxyError('Cannot connect to proxy.', timeout('timed out'))) at 56 - downloadFileFromUrl - /Users/truongthuan/Develop/python/blog/flashcard/helper.py
 2021-03-26 19:47:04.797968 : saved file entrepreneur+noun+uk.mp3 at 56 - downloadFileFromUrl - /Users/truongthuan/Develop/python/blog/flashcard/helper.py
 2021-03-26 19:47:04.815513 : Saved <VocabularyCard: entrepreneur > successfully. at 216 - searchVocabulary - /Users/truongthuan/Develop/python/blog/flashcard/search.py
 2021-03-26 19:52:03.734589 : HTTPSConnectionPool(host='www.oxfordlearnersdictionaries.com', port=443): Max retries exceeded with url: /definition/english/burdensome (Caused by ConnectTimeoutError(<urllib3.connection.HTTPSConnection object at 0x10ed952b0>, 'Connection to 191.242.178.209 timed out. (connect timeout=7)')) at 277 - check_search - /Users/truongthuan/Develop/python/blog/flashcard/search.py
 2021-03-26 19:52:10.743582 : HTTPSConnectionPool(host='www.oxfordlearnersdictionaries.com', port=443): Max retries exceeded with url: /definition/english/burdensome (Caused by ConnectTimeoutError(<urllib3.connection.HTTPSConnection object at 0x10ed8ff40>, 'Connection to 178.112.5.135 timed out. (connect timeout=7)')) at 277 - check_search - /Users/truongthuan/Develop/python/blog/flashcard/search.py
 2021-03-26 19:52:10.778437 : HTTPSConnectionPool(host='www.oxfordlearnersdictionaries.com', port=443): Max retries exceeded with url: /definition/english/burdensome (Caused by ProxyError('Cannot connect to proxy.', NewConnectionError('<urllib3.connection.HTTPSConnection object at 0x10ed8f730>: Failed to establish a new connection: [Errno 61] Connection refused'))) at 277 - check_search - /Users/truongthuan/Develop/python/blog/flashcard/search.py
 2021-03-26 19:52:17.790897 : HTTPSConnectionPool(host='www.oxfordlearnersdictionaries.com', port=443): Max retries exceeded with url: /definition/english/burdensome (Caused by ConnectTimeoutError(<urllib3.connection.HTTPSConnection object at 0x10ed89df0>, 'Connection to 45.231.75.35 timed out. (connect timeout=7)')) at 277 - check_search - /Users/truongthuan/Develop/python/blog/flashcard/search.py
 2021-03-26 19:52:18.582623 : saved file burdensome+adjective+us.mp3 at 56 - downloadFileFromUrl - /Users/truongthuan/Develop/python/blog/flashcard/helper.py
 2021-03-26 19:52:18.818590 : saved file burdensome+adjective+uk.mp3 at 56 - downloadFileFromUrl - /Users/truongthuan/Develop/python/blog/flashcard/helper.py
 2021-03-26 19:52:18.832660 : Saved <VocabularyCard: burdensome > successfully. at 216 - searchVocabulary - /Users/truongthuan/Develop/python/blog/flashcard/search.py
 2021-03-26 19:56:27.928257 : HTTPSConnectionPool(host='www.oxfordlearnersdictionaries.com', port=443): Max retries exceeded with url: /definition/english/brood (Caused by ProxyError('Cannot connect to proxy.', RemoteDisconnected('Remote end closed connection without response'))) at 277 - check_search - /Users/truongthuan/Develop/python/blog/flashcard/search.py
 2021-03-26 19:56:32.737956 : saved file brood+verb+us.mp3 at 56 - downloadFileFromUrl - /Users/truongthuan/Develop/python/blog/flashcard/helper.py
 2021-03-26 19:56:34.579632 : saved file brood+verb+uk.mp3 at 56 - downloadFileFromUrl - /Users/truongthuan/Develop/python/blog/flashcard/helper.py
 2021-03-26 19:56:34.605756 : Saved <VocabularyCard: brood > successfully. at 216 - searchVocabulary - /Users/truongthuan/Develop/python/blog/flashcard/search.py
 2021-03-26 19:59:39.098807 : saved file bronze+noun+us.mp3 at 56 - downloadFileFromUrl - /Users/truongthuan/Develop/python/blog/flashcard/helper.py
 2021-03-26 19:59:52.275366 : saved file bronze+noun+uk.mp3 at 56 - downloadFileFromUrl - /Users/truongthuan/Develop/python/blog/flashcard/helper.py
 2021-03-26 19:59:52.286725 : Saved <VocabularyCard: bronze > successfully. at 216 - searchVocabulary - /Users/truongthuan/Develop/python/blog/flashcard/search.py
 2021-03-26 20:02:17.008814 : HTTPSConnectionPool(host='www.oxfordlearnersdictionaries.com', port=443): Max retries exceeded with url: /definition/english/brace (Caused by ProxyError('Cannot connect to proxy.', NewConnectionError('<urllib3.connection.HTTPSConnection object at 0x10f114340>: Failed to establish a new connection: [Errno 61] Connection refused'))) at 277 - check_search - /Users/truongthuan/Develop/python/blog/flashcard/search.py
 2021-03-26 20:02:19.877216 : HTTPSConnectionPool(host='www.oxfordlearnersdictionaries.com', port=443): Max retries exceeded with url: /definition/english/brace (Caused by SSLError(SSLCertVerificationError(1, '[SSL: CERTIFICATE_VERIFY_FAILED] certificate verify failed: self signed certificate in certificate chain (_ssl.c:1123)'))) at 277 - check_search - /Users/truongthuan/Develop/python/blog/flashcard/search.py
 2021-03-26 20:02:22.846828 : HTTPSConnectionPool(host='www.oxfordlearnersdictionaries.com', port=443): Max retries exceeded with url: /definition/english/brace (Caused by SSLError(SSLCertVerificationError(1, '[SSL: CERTIFICATE_VERIFY_FAILED] certificate verify failed: self signed certificate in certificate chain (_ssl.c:1123)'))) at 277 - check_search - /Users/truongthuan/Develop/python/blog/flashcard/search.py
 2021-03-26 20:02:23.193212 : HTTPSConnectionPool(host='www.oxfordlearnersdictionaries.com', port=443): Max retries exceeded with url: /definition/english/brace (Caused by ProxyError('Cannot connect to proxy.', NewConnectionError('<urllib3.connection.HTTPSConnection object at 0x10f13d070>: Failed to establish a new connection: [Errno 61] Connection refused'))) at 277 - check_search - /Users/truongthuan/Develop/python/blog/flashcard/search.py
 2021-03-26 20:02:27.250571 : HTTPSConnectionPool(host='www.oxfordlearnersdictionaries.com', port=443): Max retries exceeded with url: /definition/english/brace (Caused by SSLError(SSLCertVerificationError(1, '[SSL: CERTIFICATE_VERIFY_FAILED] certificate verify failed: self signed certificate in certificate chain (_ssl.c:1123)'))) at 277 - check_search - /Users/truongthuan/Develop/python/blog/flashcard/search.py
 2021-03-26 20:02:34.260038 : HTTPSConnectionPool(host='www.oxfordlearnersdictionaries.com', port=443): Max retries exceeded with url: /definition/english/brace (Caused by ConnectTimeoutError(<urllib3.connection.HTTPSConnection object at 0x10f13d910>, 'Connection to 149.125.150.250 timed out. (connect timeout=7)')) at 277 - check_search - /Users/truongthuan/Develop/python/blog/flashcard/search.py
 2021-03-26 20:02:41.276010 : HTTPSConnectionPool(host='www.oxfordlearnersdictionaries.com', port=443): Max retries exceeded with url: /definition/english/brace (Caused by ConnectTimeoutError(<urllib3.connection.HTTPSConnection object at 0x10f10bd00>, 'Connection to 103.227.254.118 timed out. (connect timeout=7)')) at 277 - check_search - /Users/truongthuan/Develop/python/blog/flashcard/search.py
 2021-03-26 20:02:50.783296 : HTTPSConnectionPool(host='www.oxfordlearnersdictionaries.com', port=443): Max retries exceeded with url: /definition/english/brace (Caused by ProxyError('Cannot connect to proxy.', RemoteDisconnected('Remote end closed connection without response'))) at 277 - check_search - /Users/truongthuan/Develop/python/blog/flashcard/search.py
 2021-03-26 20:02:56.843385 : error: HTTPSConnectionPool(host='www.oxfordlearnersdictionaries.com', port=443): Max retries exceeded with url: /media/english/us_pron/b/bra/brace/brace__us_1.mp3 (Caused by ProxyError('Cannot connect to proxy.', OSError('Tunnel connection failed: 503 Too many open connections'))) at 56 - downloadFileFromUrl - /Users/truongthuan/Develop/python/blog/flashcard/helper.py
 2021-03-26 20:02:58.482254 : error: HTTPSConnectionPool(host='www.oxfordlearnersdictionaries.com', port=443): Max retries exceeded with url: /media/english/us_pron/b/bra/brace/brace__us_1.mp3 (Caused by ProxyError('Cannot connect to proxy.', ConnectionResetError(54, 'Connection reset by peer'))) at 56 - downloadFileFromUrl - /Users/truongthuan/Develop/python/blog/flashcard/helper.py
 2021-03-26 20:03:02.403538 : error: HTTPSConnectionPool(host='www.oxfordlearnersdictionaries.com', port=443): Max retries exceeded with url: /media/english/us_pron/b/bra/brace/brace__us_1.mp3 (Caused by ProxyError('Cannot connect to proxy.', OSError('Tunnel connection failed: 503 Too many open connections'))) at 56 - downloadFileFromUrl - /Users/truongthuan/Develop/python/blog/flashcard/helper.py
 2021-03-26 20:03:03.174692 : error: HTTPSConnectionPool(host='www.oxfordlearnersdictionaries.com', port=443): Max retries exceeded with url: /media/english/us_pron/b/bra/brace/brace__us_1.mp3 (Caused by ProxyError('Cannot connect to proxy.', OSError('Tunnel connection failed: 503 Too many open connections'))) at 56 - downloadFileFromUrl - /Users/truongthuan/Develop/python/blog/flashcard/helper.py
 2021-03-26 20:03:03.872731 : error: HTTPSConnectionPool(host='www.oxfordlearnersdictionaries.com', port=443): Max retries exceeded with url: /media/english/us_pron/b/bra/brace/brace__us_1.mp3 (Caused by ProxyError('Cannot connect to proxy.', OSError('Tunnel connection failed: 503 Too many open connections'))) at 56 - downloadFileFromUrl - /Users/truongthuan/Develop/python/blog/flashcard/helper.py
 2021-03-26 20:03:06.420693 : error: HTTPSConnectionPool(host='www.oxfordlearnersdictionaries.com', port=443): Max retries exceeded with url: /media/english/us_pron/b/bra/brace/brace__us_1.mp3 (Caused by ProxyError('Cannot connect to proxy.', OSError('Tunnel connection failed: 503 Too many open connections'))) at 56 - downloadFileFromUrl - /Users/truongthuan/Develop/python/blog/flashcard/helper.py
 2021-03-26 20:03:23.434482 : error: HTTPSConnectionPool(host='www.oxfordlearnersdictionaries.com', port=443): Max retries exceeded with url: /media/english/us_pron/b/bra/brace/brace__us_1.mp3 (Caused by ConnectTimeoutError(<urllib3.connection.HTTPSConnection object at 0x10f2b5d00>, 'Connection to 167.172.184.166 timed out. (connect timeout=17)')) at 56 - downloadFileFromUrl - /Users/truongthuan/Develop/python/blog/flashcard/helper.py
 2021-03-26 20:03:28.276904 : error: [Errno 2] No such file or directory: '/Users/truongthuan/Develop/python/blog/media/audio/audio/brace+noun+us.mp3' at 56 - downloadFileFromUrl - /Users/truongthuan/Develop/python/blog/flashcard/helper.py
 2021-03-26 20:03:47.059009 : error: HTTPSConnectionPool(host='www.oxfordlearnersdictionaries.com', port=443): Max retries exceeded with url: /media/english/us_pron/b/bra/brace/brace__us_1.mp3 (Caused by ConnectTimeoutError(<urllib3.connection.HTTPSConnection object at 0x10f4ada60>, 'Connection to 152.67.48.62 timed out. (connect timeout=17)')) at 56 - downloadFileFromUrl - /Users/truongthuan/Develop/python/blog/flashcard/helper.py
 2021-03-26 20:04:04.076394 : error: HTTPSConnectionPool(host='www.oxfordlearnersdictionaries.com', port=443): Max retries exceeded with url: /media/english/us_pron/b/bra/brace/brace__us_1.mp3 (Caused by ConnectTimeoutError(<urllib3.connection.HTTPSConnection object at 0x10f4b5250>, 'Connection to 152.67.48.62 timed out. (connect timeout=17)')) at 56 - downloadFileFromUrl - /Users/truongthuan/Develop/python/blog/flashcard/helper.py
 2021-03-26 20:04:21.093743 : error: HTTPSConnectionPool(host='www.oxfordlearnersdictionaries.com', port=443): Max retries exceeded with url: /media/english/us_pron/b/bra/brace/brace__us_1.mp3 (Caused by ConnectTimeoutError(<urllib3.connection.HTTPSConnection object at 0x10f4b5a00>, 'Connection to 152.67.48.62 timed out. (connect timeout=17)')) at 56 - downloadFileFromUrl - /Users/truongthuan/Develop/python/blog/flashcard/helper.py
 2021-03-26 20:04:41.494656 : error: HTTPSConnectionPool(host='www.oxfordlearnersdictionaries.com', port=443): Max retries exceeded with url: /media/english/us_pron/b/bra/brace/brace__us_1.mp3 (Caused by ProxyError('Cannot connect to proxy.', timeout('timed out'))) at 56 - downloadFileFromUrl - /Users/truongthuan/Develop/python/blog/flashcard/helper.py
 2021-03-26 20:04:58.902383 : error: HTTPSConnectionPool(host='www.oxfordlearnersdictionaries.com', port=443): Max retries exceeded with url: /media/english/us_pron/b/bra/brace/brace__us_1.mp3 (Caused by ProxyError('Cannot connect to proxy.', timeout('timed out'))) at 56 - downloadFileFromUrl - /Users/truongthuan/Develop/python/blog/flashcard/helper.py
 2021-03-26 20:05:18.356013 : error: HTTPSConnectionPool(host='www.oxfordlearnersdictionaries.com', port=443): Max retries exceeded with url: /media/english/us_pron/b/bra/brace/brace__us_1.mp3 (Caused by ProxyError('Cannot connect to proxy.', timeout('timed out'))) at 56 - downloadFileFromUrl - /Users/truongthuan/Develop/python/blog/flashcard/helper.py
 2021-03-26 20:05:18.685316 : error: HTTPSConnectionPool(host='www.oxfordlearnersdictionaries.com', port=443): Max retries exceeded with url: /media/english/us_pron/b/bra/brace/brace__us_1.mp3 (Caused by ProxyError('Cannot connect to proxy.', OSError('Tunnel connection failed: 403 Forbidden'))) at 56 - downloadFileFromUrl - /Users/truongthuan/Develop/python/blog/flashcard/helper.py
 2021-03-26 20:05:36.275823 : error: HTTPSConnectionPool(host='www.oxfordlearnersdictionaries.com', port=443): Max retries exceeded with url: /media/english/us_pron/b/bra/brace/brace__us_1.mp3 (Caused by ProxyError('Cannot connect to proxy.', timeout('timed out'))) at 56 - downloadFileFromUrl - /Users/truongthuan/Develop/python/blog/flashcard/helper.py
 2021-03-26 20:05:38.532696 : error: HTTPSConnectionPool(host='www.oxfordlearnersdictionaries.com', port=443): Max retries exceeded with url: /media/english/us_pron/b/bra/brace/brace__us_1.mp3 (Caused by ProxyError('Cannot connect to proxy.', NewConnectionError('<urllib3.connection.HTTPSConnection object at 0x10f690e80>: Failed to establish a new connection: [Errno 61] Connection refused'))) at 56 - downloadFileFromUrl - /Users/truongthuan/Develop/python/blog/flashcard/helper.py
 2021-03-26 20:05:38.931071 : error: HTTPSConnectionPool(host='www.oxfordlearnersdictionaries.com', port=443): Max retries exceeded with url: /media/english/us_pron/b/bra/brace/brace__us_1.mp3 (Caused by ProxyError('Cannot connect to proxy.', NewConnectionError('<urllib3.connection.HTTPSConnection object at 0x10f4b8670>: Failed to establish a new connection: [Errno 61] Connection refused'))) at 56 - downloadFileFromUrl - /Users/truongthuan/Develop/python/blog/flashcard/helper.py
 2021-03-26 20:05:39.340720 : error: HTTPSConnectionPool(host='www.oxfordlearnersdictionaries.com', port=443): Max retries exceeded with url: /media/english/us_pron/b/bra/brace/brace__us_1.mp3 (Caused by ProxyError('Cannot connect to proxy.', NewConnectionError('<urllib3.connection.HTTPSConnection object at 0x10f4b8e20>: Failed to establish a new connection: [Errno 61] Connection refused'))) at 56 - downloadFileFromUrl - /Users/truongthuan/Develop/python/blog/flashcard/helper.py
 2021-03-26 20:05:39.750028 : error: HTTPSConnectionPool(host='www.oxfordlearnersdictionaries.com', port=443): Max retries exceeded with url: /media/english/us_pron/b/bra/brace/brace__us_1.mp3 (Caused by ProxyError('Cannot connect to proxy.', NewConnectionError('<urllib3.connection.HTTPSConnection object at 0x10f4c24c0>: Failed to establish a new connection: [Errno 61] Connection refused'))) at 56 - downloadFileFromUrl - /Users/truongthuan/Develop/python/blog/flashcard/helper.py
 2021-03-26 20:05:40.160185 : error: HTTPSConnectionPool(host='www.oxfordlearnersdictionaries.com', port=443): Max retries exceeded with url: /media/english/us_pron/b/bra/brace/brace__us_1.mp3 (Caused by ProxyError('Cannot connect to proxy.', NewConnectionError('<urllib3.connection.HTTPSConnection object at 0x10f4b8310>: Failed to establish a new connection: [Errno 61] Connection refused'))) at 56 - downloadFileFromUrl - /Users/truongthuan/Develop/python/blog/flashcard/helper.py
 2021-03-26 20:05:40.569964 : error: HTTPSConnectionPool(host='www.oxfordlearnersdictionaries.com', port=443): Max retries exceeded with url: /media/english/us_pron/b/bra/brace/brace__us_1.mp3 (Caused by ProxyError('Cannot connect to proxy.', NewConnectionError('<urllib3.connection.HTTPSConnection object at 0x10f6a0610>: Failed to establish a new connection: [Errno 61] Connection refused'))) at 56 - downloadFileFromUrl - /Users/truongthuan/Develop/python/blog/flashcard/helper.py
 2021-03-26 20:05:57.579516 : error: HTTPSConnectionPool(host='www.oxfordlearnersdictionaries.com', port=443): Max retries exceeded with url: /media/english/us_pron/b/bra/brace/brace__us_1.mp3 (Caused by ConnectTimeoutError(<urllib3.connection.HTTPSConnection object at 0x10f6a0dc0>, 'Connection to 198.24.170.170 timed out. (connect timeout=17)')) at 56 - downloadFileFromUrl - /Users/truongthuan/Develop/python/blog/flashcard/helper.py
 2021-03-26 20:05:58.197619 : error: HTTPSConnectionPool(host='www.oxfordlearnersdictionaries.com', port=443): Max retries exceeded with url: /media/english/us_pron/b/bra/brace/brace__us_1.mp3 (Caused by ProxyError('Cannot connect to proxy.', OSError('Tunnel connection failed: 503 Too many open connections'))) at 56 - downloadFileFromUrl - /Users/truongthuan/Develop/python/blog/flashcard/helper.py
 2021-03-26 20:08:20.719120 : HTTPSConnectionPool(host='www.oxfordlearnersdictionaries.com', port=443): Max retries exceeded with url: /definition/english/brace (Caused by ProxyError('Cannot connect to proxy.', timeout('timed out'))) at 277 - check_search - /Users/truongthuan/Develop/python/blog/flashcard/search.py
 2021-03-26 20:08:21.135574 : HTTPSConnectionPool(host='www.oxfordlearnersdictionaries.com', port=443): Max retries exceeded with url: /definition/english/brace (Caused by ProxyError('Cannot connect to proxy.', NewConnectionError('<urllib3.connection.HTTPSConnection object at 0x1097e5160>: Failed to establish a new connection: [Errno 61] Connection refused'))) at 277 - check_search - /Users/truongthuan/Develop/python/blog/flashcard/search.py
 2021-03-26 20:08:21.852857 : HTTPSConnectionPool(host='www.oxfordlearnersdictionaries.com', port=443): Max retries exceeded with url: /definition/english/brace (Caused by ProxyError('Cannot connect to proxy.', OSError('Tunnel connection failed: 500 Internal Server Error'))) at 277 - check_search - /Users/truongthuan/Develop/python/blog/flashcard/search.py
 2021-03-26 20:08:29.121437 : HTTPSConnectionPool(host='www.oxfordlearnersdictionaries.com', port=443): Max retries exceeded with url: /definition/english/brace (Caused by ProxyError('Cannot connect to proxy.', timeout('timed out'))) at 277 - check_search - /Users/truongthuan/Develop/python/blog/flashcard/search.py
 2021-03-26 20:08:59.442605 : error: HTTPSConnectionPool(host='www.oxfordlearnersdictionaries.com', port=443): Max retries exceeded with url: /media/english/us_pron/b/bra/brace/brace__us_1.mp3 (Caused by ConnectTimeoutError(<urllib3.connection.HTTPSConnection object at 0x1099866a0>, 'Connection to 62.210.69.176 timed out. (connect timeout=17)')) at 56 - downloadFileFromUrl - /Users/truongthuan/Develop/python/blog/flashcard/helper.py
 2021-03-26 20:09:23.815440 : error: HTTPSConnectionPool(host='www.oxfordlearnersdictionaries.com', port=443): Max retries exceeded with url: /media/english/us_pron/b/bra/brace/brace__us_1.mp3 (Caused by ProxyError('Cannot connect to proxy.', timeout('timed out'))) at 56 - downloadFileFromUrl - /Users/truongthuan/Develop/python/blog/flashcard/helper.py
 2021-03-26 20:09:40.826488 : error: HTTPSConnectionPool(host='www.oxfordlearnersdictionaries.com', port=443): Max retries exceeded with url: /media/english/us_pron/b/bra/brace/brace__us_1.mp3 (Caused by ConnectTimeoutError(<urllib3.connection.HTTPSConnection object at 0x109986eb0>, 'Connection to 62.210.69.176 timed out. (connect timeout=17)')) at 56 - downloadFileFromUrl - /Users/truongthuan/Develop/python/blog/flashcard/helper.py
 2021-03-26 20:10:09.177295 : error: HTTPSConnectionPool(host='www.oxfordlearnersdictionaries.com', port=443): Max retries exceeded with url: /media/english/us_pron/b/bra/brace/brace__us_1.mp3 (Caused by ProxyError('Cannot connect to proxy.', timeout('timed out'))) at 56 - downloadFileFromUrl - /Users/truongthuan/Develop/python/blog/flashcard/helper.py
 2021-03-26 20:10:26.194141 : error: HTTPSConnectionPool(host='www.oxfordlearnersdictionaries.com', port=443): Max retries exceeded with url: /media/english/us_pron/b/bra/brace/brace__us_1.mp3 (Caused by ConnectTimeoutError(<urllib3.connection.HTTPSConnection object at 0x1097e5070>, 'Connection to 62.210.69.176 timed out. (connect timeout=17)')) at 56 - downloadFileFromUrl - /Users/truongthuan/Develop/python/blog/flashcard/helper.py
 2021-03-26 20:10:44.502568 : error: HTTPSConnectionPool(host='www.oxfordlearnersdictionaries.com', port=443): Max retries exceeded with url: /media/english/us_pron/b/bra/brace/brace__us_1.mp3 (Caused by ProxyError('Cannot connect to proxy.', timeout('timed out'))) at 56 - downloadFileFromUrl - /Users/truongthuan/Develop/python/blog/flashcard/helper.py
 2021-03-26 20:11:01.516177 : error: HTTPSConnectionPool(host='www.oxfordlearnersdictionaries.com', port=443): Max retries exceeded with url: /media/english/us_pron/b/bra/brace/brace__us_1.mp3 (Caused by ConnectTimeoutError(<urllib3.connection.HTTPSConnection object at 0x10998b7c0>, 'Connection to 78.110.154.177 timed out. (connect timeout=17)')) at 56 - downloadFileFromUrl - /Users/truongthuan/Develop/python/blog/flashcard/helper.py
 2021-03-26 20:11:18.528556 : error: HTTPSConnectionPool(host='www.oxfordlearnersdictionaries.com', port=443): Max retries exceeded with url: /media/english/us_pron/b/bra/brace/brace__us_1.mp3 (Caused by ConnectTimeoutError(<urllib3.connection.HTTPSConnection object at 0x10998beb0>, 'Connection to 37.120.192.154 timed out. (connect timeout=17)')) at 56 - downloadFileFromUrl - /Users/truongthuan/Develop/python/blog/flashcard/helper.py
 2021-03-26 20:11:23.074747 : saved file brace+noun+us.mp3 at 56 - downloadFileFromUrl - /Users/truongthuan/Develop/python/blog/flashcard/helper.py
 2021-03-26 20:11:42.457151 : error: HTTPSConnectionPool(host='www.oxfordlearnersdictionaries.com', port=443): Max retries exceeded with url: /media/english/uk_pron/b/bra/brace/brace__gb_1.mp3 (Caused by ProxyError('Cannot connect to proxy.', timeout('timed out'))) at 56 - downloadFileFromUrl - /Users/truongthuan/Develop/python/blog/flashcard/helper.py
 2021-03-26 20:11:48.086653 : error: HTTPSConnectionPool(host='www.oxfordlearnersdictionaries.com', port=443): Max retries exceeded with url: /media/english/uk_pron/b/bra/brace/brace__gb_1.mp3 (Caused by ProxyError('Cannot connect to proxy.', RemoteDisconnected('Remote end closed connection without response'))) at 56 - downloadFileFromUrl - /Users/truongthuan/Develop/python/blog/flashcard/helper.py
 2021-03-26 20:11:56.284341 : saved file brace+noun+uk.mp3 at 56 - downloadFileFromUrl - /Users/truongthuan/Develop/python/blog/flashcard/helper.py
 2021-03-26 20:11:56.309209 : Saved <VocabularyCard: brace > successfully. at 216 - searchVocabulary - /Users/truongthuan/Develop/python/blog/flashcard/search.py
 2021-03-26 20:14:39.122282 : HTTPSConnectionPool(host='www.oxfordlearnersdictionaries.com', port=443): Max retries exceeded with url: /definition/english/brilliance (Caused by ConnectTimeoutError(<urllib3.connection.HTTPSConnection object at 0x104bde700>, 'Connection to 62.210.69.176 timed out. (connect timeout=7)')) at 278 - check_search - /Users/truongthuan/Develop/python/blog/flashcard/search.py
 2021-03-26 20:15:05.210982 : saved file brilliance+noun+us.mp3 at 56 - downloadFileFromUrl - /Users/truongthuan/Develop/python/blog/flashcard/helper.py
 2021-03-26 20:15:24.530597 : error: HTTPSConnectionPool(host='www.oxfordlearnersdictionaries.com', port=443): Max retries exceeded with url: /media/english/uk_pron/b/bri/brill/brilliance__gb_1.mp3 (Caused by ProxyError('Cannot connect to proxy.', timeout('timed out'))) at 56 - downloadFileFromUrl - /Users/truongthuan/Develop/python/blog/flashcard/helper.py
 2021-03-26 20:15:41.541522 : error: HTTPSConnectionPool(host='www.oxfordlearnersdictionaries.com', port=443): Max retries exceeded with url: /media/english/uk_pron/b/bri/brill/brilliance__gb_1.mp3 (Caused by ConnectTimeoutError(<urllib3.connection.HTTPSConnection object at 0x104d1b0a0>, 'Connection to 178.112.5.135 timed out. (connect timeout=17)')) at 56 - downloadFileFromUrl - /Users/truongthuan/Develop/python/blog/flashcard/helper.py
 2021-03-26 20:15:58.556353 : error: HTTPSConnectionPool(host='www.oxfordlearnersdictionaries.com', port=443): Max retries exceeded with url: /media/english/uk_pron/b/bri/brill/brilliance__gb_1.mp3 (Caused by ConnectTimeoutError(<urllib3.connection.HTTPSConnection object at 0x104d1b850>, 'Connection to 178.112.5.135 timed out. (connect timeout=17)')) at 56 - downloadFileFromUrl - /Users/truongthuan/Develop/python/blog/flashcard/helper.py
 2021-03-26 20:16:18.956902 : error: HTTPSConnectionPool(host='www.oxfordlearnersdictionaries.com', port=443): Max retries exceeded with url: /media/english/uk_pron/b/bri/brill/brilliance__gb_1.mp3 (Caused by ProxyError('Cannot connect to proxy.', timeout('timed out'))) at 56 - downloadFileFromUrl - /Users/truongthuan/Develop/python/blog/flashcard/helper.py
 2021-03-26 20:16:38.314079 : error: HTTPSConnectionPool(host='www.oxfordlearnersdictionaries.com', port=443): Max retries exceeded with url: /media/english/uk_pron/b/bri/brill/brilliance__gb_1.mp3 (Caused by ProxyError('Cannot connect to proxy.', timeout('timed out'))) at 56 - downloadFileFromUrl - /Users/truongthuan/Develop/python/blog/flashcard/helper.py
 2021-03-26 20:16:44.365889 : saved file brilliance+noun+uk.mp3 at 56 - downloadFileFromUrl - /Users/truongthuan/Develop/python/blog/flashcard/helper.py
 2021-03-26 20:16:44.367721 : "<VocabularyCard: VocabularyCard: brilliance >" needs to have a value for field "id" before this many-to-many relationship can be used. at 278 - check_search - /Users/truongthuan/Develop/python/blog/flashcard/search.py
 2021-03-26 20:16:53.664209 : HTTPSConnectionPool(host='www.oxfordlearnersdictionaries.com', port=443): Max retries exceeded with url: /definition/english/brilliance (Caused by ProxyError('Cannot connect to proxy.', timeout('timed out'))) at 278 - check_search - /Users/truongthuan/Develop/python/blog/flashcard/search.py
 2021-03-26 20:16:54.487692 : HTTPSConnectionPool(host='www.oxfordlearnersdictionaries.com', port=443): Max retries exceeded with url: /definition/english/brilliance (Caused by ProxyError('Cannot connect to proxy.', RemoteDisconnected('Remote end closed connection without response'))) at 278 - check_search - /Users/truongthuan/Develop/python/blog/flashcard/search.py
 2021-03-26 20:16:54.755872 : HTTPSConnectionPool(host='www.oxfordlearnersdictionaries.com', port=443): Max retries exceeded with url: /definition/english/brilliance (Caused by ProxyError('Cannot connect to proxy.', NewConnectionError('<urllib3.connection.HTTPSConnection object at 0x104d2ab50>: Failed to establish a new connection: [Errno 61] Connection refused'))) at 278 - check_search - /Users/truongthuan/Develop/python/blog/flashcard/search.py
 2021-03-26 20:17:00.020842 : HTTPSConnectionPool(host='www.oxfordlearnersdictionaries.com', port=443): Max retries exceeded with url: /definition/english/brilliance (Caused by ProxyError('Cannot connect to proxy.', RemoteDisconnected('Remote end closed connection without response'))) at 278 - check_search - /Users/truongthuan/Develop/python/blog/flashcard/search.py
 2021-03-26 20:17:00.838927 : HTTPSConnectionPool(host='www.oxfordlearnersdictionaries.com', port=443): Max retries exceeded with url: /definition/english/brilliance (Caused by ProxyError('Cannot connect to proxy.', OSError('Tunnel connection failed: 500 Internal Server Error'))) at 278 - check_search - /Users/truongthuan/Develop/python/blog/flashcard/search.py
 2021-03-26 20:17:04.216256 : HTTPSConnectionPool(host='www.oxfordlearnersdictionaries.com', port=443): Max retries exceeded with url: /definition/english/brilliance (Caused by ProxyError('Cannot connect to proxy.', OSError('Tunnel connection failed: 503 Too many open connections'))) at 278 - check_search - /Users/truongthuan/Develop/python/blog/flashcard/search.py
 2021-03-26 20:17:11.223872 : HTTPSConnectionPool(host='www.oxfordlearnersdictionaries.com', port=443): Max retries exceeded with url: /definition/english/brilliance (Caused by ConnectTimeoutError(<urllib3.connection.HTTPSConnection object at 0x104d2a640>, 'Connection to 167.71.41.173 timed out. (connect timeout=7)')) at 278 - check_search - /Users/truongthuan/Develop/python/blog/flashcard/search.py
 2021-03-26 20:17:12.599712 : HTTPSConnectionPool(host='www.oxfordlearnersdictionaries.com', port=443): Max retries exceeded with url: /definition/english/brilliance (Caused by ProxyError('Cannot connect to proxy.', OSError('Tunnel connection failed: 500 Internal Server Error'))) at 278 - check_search - /Users/truongthuan/Develop/python/blog/flashcard/search.py
 2021-03-26 20:17:12.649595 : HTTPSConnectionPool(host='www.oxfordlearnersdictionaries.com', port=443): Max retries exceeded with url: /definition/english/brilliance (Caused by ProxyError('Cannot connect to proxy.', NewConnectionError('<urllib3.connection.HTTPSConnection object at 0x104e79190>: Failed to establish a new connection: [Errno 61] Connection refused'))) at 278 - check_search - /Users/truongthuan/Develop/python/blog/flashcard/search.py
 2021-03-26 20:17:13.946271 : HTTPSConnectionPool(host='www.oxfordlearnersdictionaries.com', port=443): Max retries exceeded with url: /definition/english/brilliance (Caused by ProxyError('Cannot connect to proxy.', NewConnectionError('<urllib3.connection.HTTPSConnection object at 0x104e798e0>: Failed to establish a new connection: [Errno 61] Connection refused'))) at 278 - check_search - /Users/truongthuan/Develop/python/blog/flashcard/search.py
 2021-03-26 20:17:14.355169 : HTTPSConnectionPool(host='www.oxfordlearnersdictionaries.com', port=443): Max retries exceeded with url: /definition/english/brilliance (Caused by ProxyError('Cannot connect to proxy.', NewConnectionError('<urllib3.connection.HTTPSConnection object at 0x104e84100>: Failed to establish a new connection: [Errno 61] Connection refused'))) at 278 - check_search - /Users/truongthuan/Develop/python/blog/flashcard/search.py
 2021-03-26 20:17:21.365634 : HTTPSConnectionPool(host='www.oxfordlearnersdictionaries.com', port=443): Max retries exceeded with url: /definition/english/brilliance (Caused by ConnectTimeoutError(<urllib3.connection.HTTPSConnection object at 0x104e848e0>, 'Connection to 149.125.150.250 timed out. (connect timeout=7)')) at 278 - check_search - /Users/truongthuan/Develop/python/blog/flashcard/search.py
 2021-03-26 20:17:28.734329 : HTTPSConnectionPool(host='www.oxfordlearnersdictionaries.com', port=443): Max retries exceeded with url: /definition/english/brilliance (Caused by ProxyError('Cannot connect to proxy.', timeout('timed out'))) at 278 - check_search - /Users/truongthuan/Develop/python/blog/flashcard/search.py
 2021-03-26 20:17:38.154189 : HTTPSConnectionPool(host='www.oxfordlearnersdictionaries.com', port=443): Max retries exceeded with url: /definition/english/brilliance (Caused by ProxyError('Cannot connect to proxy.', timeout('timed out'))) at 278 - check_search - /Users/truongthuan/Develop/python/blog/flashcard/search.py
 2021-03-26 20:17:38.522117 : HTTPSConnectionPool(host='www.oxfordlearnersdictionaries.com', port=443): Max retries exceeded with url: /definition/english/brilliance (Caused by ProxyError('Cannot connect to proxy.', NewConnectionError('<urllib3.connection.HTTPSConnection object at 0x104e90100>: Failed to establish a new connection: [Errno 61] Connection refused'))) at 278 - check_search - /Users/truongthuan/Develop/python/blog/flashcard/search.py
 2021-03-26 20:17:46.857912 : HTTPSConnectionPool(host='www.oxfordlearnersdictionaries.com', port=443): Max retries exceeded with url: /definition/english/brilliance (Caused by ProxyError('Cannot connect to proxy.', timeout('timed out'))) at 278 - check_search - /Users/truongthuan/Develop/python/blog/flashcard/search.py
 2021-03-26 20:17:46.858242 : Break search <<brilliance>> at 278 - check_search - /Users/truongthuan/Develop/python/blog/flashcard/search.py
 2021-03-26 20:18:25.726222 : HTTPSConnectionPool(host='www.oxfordlearnersdictionaries.com', port=443): Max retries exceeded with url: /definition/english/brilliance (Caused by ProxyError('Cannot connect to proxy.', NewConnectionError('<urllib3.connection.HTTPSConnection object at 0x109dfd1f0>: Failed to establish a new connection: [Errno 61] Connection refused'))) at 278 - check_search - /Users/truongthuan/Develop/python/blog/flashcard/search.py
 2021-03-26 20:19:00.242276 : error: HTTPSConnectionPool(host='www.oxfordlearnersdictionaries.com', port=443): Max retries exceeded with url: /media/english/us_pron/b/bri/brill/brilliance__us_1.mp3 (Caused by ProxyError('Cannot connect to proxy.', timeout('timed out'))) at 56 - downloadFileFromUrl - /Users/truongthuan/Develop/python/blog/flashcard/helper.py
 2021-03-26 20:19:03.316827 : saved file brilliance+noun+us.mp3 at 56 - downloadFileFromUrl - /Users/truongthuan/Develop/python/blog/flashcard/helper.py
 2021-03-26 20:19:27.172448 : saved file brilliance+noun+uk.mp3 at 56 - downloadFileFromUrl - /Users/truongthuan/Develop/python/blog/flashcard/helper.py
 2021-03-26 20:19:27.173965 : "<VocabularyCard: VocabularyCard: brilliance >" needs to have a value for field "id" before this many-to-many relationship can be used. at 278 - check_search - /Users/truongthuan/Develop/python/blog/flashcard/search.py
 2021-03-26 20:19:29.219126 : HTTPSConnectionPool(host='www.oxfordlearnersdictionaries.com', port=443): Max retries exceeded with url: /definition/english/brilliance (Caused by SSLError(SSLCertVerificationError(1, '[SSL: CERTIFICATE_VERIFY_FAILED] certificate verify failed: self signed certificate in certificate chain (_ssl.c:1123)'))) at 278 - check_search - /Users/truongthuan/Develop/python/blog/flashcard/search.py
 2021-03-26 20:19:30.253605 : HTTPSConnectionPool(host='www.oxfordlearnersdictionaries.com', port=443): Max retries exceeded with url: /definition/english/brilliance (Caused by ProxyError('Cannot connect to proxy.', NewConnectionError('<urllib3.connection.HTTPSConnection object at 0x109f3a8b0>: Failed to establish a new connection: [Errno 61] Connection refused'))) at 278 - check_search - /Users/truongthuan/Develop/python/blog/flashcard/search.py
 2021-03-26 20:19:35.362969 : saved file brilliance+noun+us.mp3 at 56 - downloadFileFromUrl - /Users/truongthuan/Develop/python/blog/flashcard/helper.py
 2021-03-26 20:19:37.415750 : saved file brilliance+noun+uk.mp3 at 56 - downloadFileFromUrl - /Users/truongthuan/Develop/python/blog/flashcard/helper.py
 2021-03-26 20:19:37.416653 : "<VocabularyCard: VocabularyCard: brilliance >" needs to have a value for field "id" before this many-to-many relationship can be used. at 278 - check_search - /Users/truongthuan/Develop/python/blog/flashcard/search.py
 2021-03-26 20:21:08.778037 : error: HTTPSConnectionPool(host='www.oxfordlearnersdictionaries.com', port=443): Max retries exceeded with url: /media/english/us_pron/b/bri/brill/brilliance__us_1.mp3 (Caused by ConnectTimeoutError(<urllib3.connection.HTTPSConnection object at 0x10f370460>, 'Connection to 103.227.254.118 timed out. (connect timeout=17)')) at 56 - downloadFileFromUrl - /Users/truongthuan/Develop/python/blog/flashcard/helper.py
 2021-03-26 20:21:29.007958 : error: HTTPSConnectionPool(host='www.oxfordlearnersdictionaries.com', port=443): Max retries exceeded with url: /media/english/us_pron/b/bri/brill/brilliance__us_1.mp3 (Caused by ProxyError('Cannot connect to proxy.', ConnectionResetError(54, 'Connection reset by peer'))) at 56 - downloadFileFromUrl - /Users/truongthuan/Develop/python/blog/flashcard/helper.py
 2021-03-26 20:21:46.043701 : error: HTTPSConnectionPool(host='www.oxfordlearnersdictionaries.com', port=443): Max retries exceeded with url: /media/english/us_pron/b/bri/brill/brilliance__us_1.mp3 (Caused by ConnectTimeoutError(<urllib3.connection.HTTPSConnection object at 0x10f370370>, 'Connection to 103.227.254.118 timed out. (connect timeout=17)')) at 56 - downloadFileFromUrl - /Users/truongthuan/Develop/python/blog/flashcard/helper.py
 2021-03-26 20:22:03.054647 : error: HTTPSConnectionPool(host='www.oxfordlearnersdictionaries.com', port=443): Max retries exceeded with url: /media/english/us_pron/b/bri/brill/brilliance__us_1.mp3 (Caused by ConnectTimeoutError(<urllib3.connection.HTTPSConnection object at 0x10f370ca0>, 'Connection to 103.227.254.118 timed out. (connect timeout=17)')) at 56 - downloadFileFromUrl - /Users/truongthuan/Develop/python/blog/flashcard/helper.py
 2021-03-26 20:22:20.070454 : error: HTTPSConnectionPool(host='www.oxfordlearnersdictionaries.com', port=443): Max retries exceeded with url: /media/english/us_pron/b/bri/brill/brilliance__us_1.mp3 (Caused by ConnectTimeoutError(<urllib3.connection.HTTPSConnection object at 0x10f37a4c0>, 'Connection to 103.227.254.118 timed out. (connect timeout=17)')) at 56 - downloadFileFromUrl - /Users/truongthuan/Develop/python/blog/flashcard/helper.py
 2021-03-26 20:22:49.736971 : error: HTTPSConnectionPool(host='www.oxfordlearnersdictionaries.com', port=443): Max retries exceeded with url: /media/english/us_pron/b/bri/brill/brilliance__us_1.mp3 (Caused by ProxyError('Cannot connect to proxy.', timeout('_ssl.c:1106: The handshake operation timed out'))) at 56 - downloadFileFromUrl - /Users/truongthuan/Develop/python/blog/flashcard/helper.py
 2021-03-26 20:23:06.754416 : error: HTTPSConnectionPool(host='www.oxfordlearnersdictionaries.com', port=443): Max retries exceeded with url: /media/english/us_pron/b/bri/brill/brilliance__us_1.mp3 (Caused by ConnectTimeoutError(<urllib3.connection.HTTPSConnection object at 0x10f37ad90>, 'Connection to 83.209.186.156 timed out. (connect timeout=17)')) at 56 - downloadFileFromUrl - /Users/truongthuan/Develop/python/blog/flashcard/helper.py
 2021-03-26 20:23:17.371133 : saved file brilliance+noun+us.mp3 at 56 - downloadFileFromUrl - /Users/truongthuan/Develop/python/blog/flashcard/helper.py
 2021-03-26 20:23:30.075903 : saved file brilliance+noun+uk.mp3 at 56 - downloadFileFromUrl - /Users/truongthuan/Develop/python/blog/flashcard/helper.py
 2021-03-26 20:23:30.094866 : Saved <VocabularyCard: brilliance > successfully. at 216 - searchVocabulary - /Users/truongthuan/Develop/python/blog/flashcard/search.py
 2021-03-26 20:26:30.862296 : HTTPSConnectionPool(host='www.oxfordlearnersdictionaries.com', port=443): Max retries exceeded with url: /definition/english/bureaucracy (Caused by ConnectTimeoutError(<urllib3.connection.HTTPSConnection object at 0x109a2f070>, 'Connection to 45.231.75.35 timed out. (connect timeout=7)')) at 279 - check_search - /Users/truongthuan/Develop/python/blog/flashcard/search.py
 2021-03-26 20:26:41.170439 : HTTPSConnectionPool(host='www.oxfordlearnersdictionaries.com', port=443): Max retries exceeded with url: /definition/english/bureaucracy (Caused by ProxyError('Cannot connect to proxy.', timeout('timed out'))) at 279 - check_search - /Users/truongthuan/Develop/python/blog/flashcard/search.py
 2021-03-26 20:26:50.951737 : HTTPSConnectionPool(host='www.oxfordlearnersdictionaries.com', port=443): Max retries exceeded with url: /definition/english/bureaucracy (Caused by ProxyError('Cannot connect to proxy.', timeout('_ssl.c:1106: The handshake operation timed out'))) at 279 - check_search - /Users/truongthuan/Develop/python/blog/flashcard/search.py
 2021-03-26 20:26:51.217286 : HTTPSConnectionPool(host='www.oxfordlearnersdictionaries.com', port=443): Max retries exceeded with url: /definition/english/bureaucracy (Caused by ProxyError('Cannot connect to proxy.', NewConnectionError('<urllib3.connection.HTTPSConnection object at 0x109a2fa30>: Failed to establish a new connection: [Errno 61] Connection refused'))) at 279 - check_search - /Users/truongthuan/Develop/python/blog/flashcard/search.py
 2021-03-26 20:27:00.657658 : HTTPSConnectionPool(host='www.oxfordlearnersdictionaries.com', port=443): Max retries exceeded with url: /definition/english/bureaucracy (Caused by ProxyError('Cannot connect to proxy.', timeout('_ssl.c:1106: The handshake operation timed out'))) at 279 - check_search - /Users/truongthuan/Develop/python/blog/flashcard/search.py
 2021-03-26 20:27:07.674519 : HTTPSConnectionPool(host='www.oxfordlearnersdictionaries.com', port=443): Max retries exceeded with url: /definition/english/bureaucracy (Caused by ConnectTimeoutError(<urllib3.connection.HTTPSConnection object at 0x109a45160>, 'Connection to 45.231.75.35 timed out. (connect timeout=7)')) at 279 - check_search - /Users/truongthuan/Develop/python/blog/flashcard/search.py
 2021-03-26 20:27:14.681782 : HTTPSConnectionPool(host='www.oxfordlearnersdictionaries.com', port=443): Max retries exceeded with url: /definition/english/bureaucracy (Caused by ConnectTimeoutError(<urllib3.connection.HTTPSConnection object at 0x1095c50d0>, 'Connection to 149.125.150.250 timed out. (connect timeout=7)')) at 279 - check_search - /Users/truongthuan/Develop/python/blog/flashcard/search.py
 2021-03-26 20:27:21.692338 : HTTPSConnectionPool(host='www.oxfordlearnersdictionaries.com', port=443): Max retries exceeded with url: /definition/english/bureaucracy (Caused by ConnectTimeoutError(<urllib3.connection.HTTPSConnection object at 0x109a2f1c0>, 'Connection to 178.112.5.135 timed out. (connect timeout=7)')) at 279 - check_search - /Users/truongthuan/Develop/python/blog/flashcard/search.py
 2021-03-26 20:27:28.703105 : HTTPSConnectionPool(host='www.oxfordlearnersdictionaries.com', port=443): Max retries exceeded with url: /definition/english/bureaucracy (Caused by ConnectTimeoutError(<urllib3.connection.HTTPSConnection object at 0x109a0ba60>, 'Connection to 62.210.69.176 timed out. (connect timeout=7)')) at 279 - check_search - /Users/truongthuan/Develop/python/blog/flashcard/search.py
 2021-03-26 20:27:53.996728 : error: HTTPSConnectionPool(host='www.oxfordlearnersdictionaries.com', port=443): Max retries exceeded with url: /media/english/us_pron/b/bur/burea/bureaucracy__us_1.mp3 (Caused by ConnectTimeoutError(<urllib3.connection.HTTPSConnection object at 0x109d5e5e0>, 'Connection to 45.231.75.35 timed out. (connect timeout=17)')) at 56 - downloadFileFromUrl - /Users/truongthuan/Develop/python/blog/flashcard/helper.py
 2021-03-26 20:28:15.167317 : error: HTTPSConnectionPool(host='www.oxfordlearnersdictionaries.com', port=443): Max retries exceeded with url: /media/english/us_pron/b/bur/burea/bureaucracy__us_1.mp3 (Caused by ProxyError('Cannot connect to proxy.', timeout('_ssl.c:1106: The handshake operation timed out'))) at 56 - downloadFileFromUrl - /Users/truongthuan/Develop/python/blog/flashcard/helper.py
 2021-03-26 20:28:34.609785 : error: HTTPSConnectionPool(host='www.oxfordlearnersdictionaries.com', port=443): Max retries exceeded with url: /media/english/us_pron/b/bur/burea/bureaucracy__us_1.mp3 (Caused by ProxyError('Cannot connect to proxy.', timeout('timed out'))) at 56 - downloadFileFromUrl - /Users/truongthuan/Develop/python/blog/flashcard/helper.py
 2021-03-26 20:28:51.996265 : error: HTTPSConnectionPool(host='www.oxfordlearnersdictionaries.com', port=443): Max retries exceeded with url: /media/english/us_pron/b/bur/burea/bureaucracy__us_1.mp3 (Caused by ProxyError('Cannot connect to proxy.', timeout('timed out'))) at 56 - downloadFileFromUrl - /Users/truongthuan/Develop/python/blog/flashcard/helper.py
 2021-03-26 20:29:13.839351 : error: HTTPSConnectionPool(host='www.oxfordlearnersdictionaries.com', port=443): Max retries exceeded with url: /media/english/us_pron/b/bur/burea/bureaucracy__us_1.mp3 (Caused by ProxyError('Cannot connect to proxy.', timeout('_ssl.c:1106: The handshake operation timed out'))) at 56 - downloadFileFromUrl - /Users/truongthuan/Develop/python/blog/flashcard/helper.py
 2021-03-26 20:29:32.258652 : error: HTTPSConnectionPool(host='www.oxfordlearnersdictionaries.com', port=443): Max retries exceeded with url: /media/english/us_pron/b/bur/burea/bureaucracy__us_1.mp3 (Caused by ProxyError('Cannot connect to proxy.', timeout('timed out'))) at 56 - downloadFileFromUrl - /Users/truongthuan/Develop/python/blog/flashcard/helper.py
 2021-03-26 20:30:09.329565 : error: HTTPSConnectionPool(host='www.oxfordlearnersdictionaries.com', port=443): Read timed out. (read timeout=17) at 56 - downloadFileFromUrl - /Users/truongthuan/Develop/python/blog/flashcard/helper.py
 2021-03-26 20:30:10.733279 : saved file bureaucracy+noun+us.mp3 at 56 - downloadFileFromUrl - /Users/truongthuan/Develop/python/blog/flashcard/helper.py
 2021-03-26 20:30:27.744005 : error: HTTPSConnectionPool(host='www.oxfordlearnersdictionaries.com', port=443): Max retries exceeded with url: /media/english/uk_pron/b/bur/burea/bureaucracy__gb_1.mp3 (Caused by ConnectTimeoutError(<urllib3.connection.HTTPSConnection object at 0x109d7b160>, 'Connection to 45.231.75.35 timed out. (connect timeout=17)')) at 56 - downloadFileFromUrl - /Users/truongthuan/Develop/python/blog/flashcard/helper.py
 2021-03-26 20:30:56.952925 : error: HTTPSConnectionPool(host='www.oxfordlearnersdictionaries.com', port=443): Max retries exceeded with url: /media/english/uk_pron/b/bur/burea/bureaucracy__gb_1.mp3 (Caused by ProxyError('Cannot connect to proxy.', timeout('_ssl.c:1106: The handshake operation timed out'))) at 56 - downloadFileFromUrl - /Users/truongthuan/Develop/python/blog/flashcard/helper.py
 2021-03-26 20:31:13.971369 : error: HTTPSConnectionPool(host='www.oxfordlearnersdictionaries.com', port=443): Max retries exceeded with url: /media/english/uk_pron/b/bur/burea/bureaucracy__gb_1.mp3 (Caused by ConnectTimeoutError(<urllib3.connection.HTTPSConnection object at 0x109d70310>, 'Connection to 45.231.75.35 timed out. (connect timeout=17)')) at 56 - downloadFileFromUrl - /Users/truongthuan/Develop/python/blog/flashcard/helper.py
 2021-03-26 20:31:34.425005 : error: HTTPSConnectionPool(host='www.oxfordlearnersdictionaries.com', port=443): Max retries exceeded with url: /media/english/uk_pron/b/bur/burea/bureaucracy__gb_1.mp3 (Caused by ProxyError('Cannot connect to proxy.', timeout('timed out'))) at 56 - downloadFileFromUrl - /Users/truongthuan/Develop/python/blog/flashcard/helper.py
 2021-03-26 20:31:57.782690 : error: HTTPSConnectionPool(host='www.oxfordlearnersdictionaries.com', port=443): Max retries exceeded with url: /media/english/uk_pron/b/bur/burea/bureaucracy__gb_1.mp3 (Caused by ProxyError('Cannot connect to proxy.', timeout('_ssl.c:1106: The handshake operation timed out'))) at 56 - downloadFileFromUrl - /Users/truongthuan/Develop/python/blog/flashcard/helper.py
 2021-03-26 20:32:20.413393 : error: HTTPSConnectionPool(host='www.oxfordlearnersdictionaries.com', port=443): Max retries exceeded with url: /media/english/uk_pron/b/bur/burea/bureaucracy__gb_1.mp3 (Caused by ProxyError('Cannot connect to proxy.', timeout('_ssl.c:1106: The handshake operation timed out'))) at 56 - downloadFileFromUrl - /Users/truongthuan/Develop/python/blog/flashcard/helper.py
 2021-03-26 20:32:28.175439 : error: HTTPSConnectionPool(host='www.oxfordlearnersdictionaries.com', port=443): Max retries exceeded with url: /media/english/uk_pron/b/bur/burea/bureaucracy__gb_1.mp3 (Caused by ProxyError('Cannot connect to proxy.', NewConnectionError('<urllib3.connection.HTTPSConnection object at 0x109d5edc0>: Failed to establish a new connection: [Errno 61] Connection refused'))) at 56 - downloadFileFromUrl - /Users/truongthuan/Develop/python/blog/flashcard/helper.py
 2021-03-26 20:32:33.807194 : error: HTTPSConnectionPool(host='www.oxfordlearnersdictionaries.com', port=443): Max retries exceeded with url: /media/english/uk_pron/b/bur/burea/bureaucracy__gb_1.mp3 (Caused by ProxyError('Cannot connect to proxy.', NewConnectionError('<urllib3.connection.HTTPSConnection object at 0x109d5e160>: Failed to establish a new connection: [Errno 61] Connection refused'))) at 56 - downloadFileFromUrl - /Users/truongthuan/Develop/python/blog/flashcard/helper.py
 2021-03-26 20:32:52.115117 : error: HTTPSConnectionPool(host='www.oxfordlearnersdictionaries.com', port=443): Max retries exceeded with url: /media/english/uk_pron/b/bur/burea/bureaucracy__gb_1.mp3 (Caused by ProxyError('Cannot connect to proxy.', timeout('timed out'))) at 56 - downloadFileFromUrl - /Users/truongthuan/Develop/python/blog/flashcard/helper.py
 2021-03-26 20:33:09.156886 : error: HTTPSConnectionPool(host='www.oxfordlearnersdictionaries.com', port=443): Max retries exceeded with url: /media/english/uk_pron/b/bur/burea/bureaucracy__gb_1.mp3 (Caused by ConnectTimeoutError(<urllib3.connection.HTTPSConnection object at 0x109f4aeb0>, 'Connection to 128.134.187.111 timed out. (connect timeout=17)')) at 56 - downloadFileFromUrl - /Users/truongthuan/Develop/python/blog/flashcard/helper.py
 2021-03-26 20:33:22.949905 : saved file bureaucracy+noun+uk.mp3 at 56 - downloadFileFromUrl - /Users/truongthuan/Develop/python/blog/flashcard/helper.py
 2021-03-26 20:33:22.986542 : Field 'id' expected a number but got (). at 279 - check_search - /Users/truongthuan/Develop/python/blog/flashcard/search.py
 2021-03-26 20:33:34.161003 : saved file bureaucracy+noun+us.mp3 at 56 - downloadFileFromUrl - /Users/truongthuan/Develop/python/blog/flashcard/helper.py
 2021-03-26 20:33:37.202323 : saved file bureaucracy+noun+uk.mp3 at 56 - downloadFileFromUrl - /Users/truongthuan/Develop/python/blog/flashcard/helper.py
 2021-03-26 20:33:37.204939 : Field 'id' expected a number but got (). at 279 - check_search - /Users/truongthuan/Develop/python/blog/flashcard/search.py
 2021-03-26 20:33:41.271283 : HTTPSConnectionPool(host='www.oxfordlearnersdictionaries.com', port=443): Max retries exceeded with url: /definition/english/bureaucracy (Caused by SSLError(SSLCertVerificationError(1, '[SSL: CERTIFICATE_VERIFY_FAILED] certificate verify failed: self signed certificate in certificate chain (_ssl.c:1123)'))) at 279 - check_search - /Users/truongthuan/Develop/python/blog/flashcard/search.py
 2021-03-26 20:37:08.531515 : HTTPSConnectionPool(host='www.oxfordlearnersdictionaries.com', port=443): Max retries exceeded with url: /definition/english/bureaucracy (Caused by SSLError(SSLCertVerificationError(1, '[SSL: CERTIFICATE_VERIFY_FAILED] certificate verify failed: self signed certificate in certificate chain (_ssl.c:1123)'))) at 279 - check_search - /Users/truongthuan/Develop/python/blog/flashcard/search.py
 2021-03-26 20:37:08.837853 : HTTPSConnectionPool(host='www.oxfordlearnersdictionaries.com', port=443): Max retries exceeded with url: /definition/english/bureaucracy (Caused by ProxyError('Cannot connect to proxy.', NewConnectionError('<urllib3.connection.HTTPSConnection object at 0x10385f4f0>: Failed to establish a new connection: [Errno 61] Connection refused'))) at 279 - check_search - /Users/truongthuan/Develop/python/blog/flashcard/search.py
 2021-03-26 20:37:15.844493 : HTTPSConnectionPool(host='www.oxfordlearnersdictionaries.com', port=443): Max retries exceeded with url: /definition/english/bureaucracy (Caused by ConnectTimeoutError(<urllib3.connection.HTTPSConnection object at 0x10385fd30>, 'Connection to 139.162.169.174 timed out. (connect timeout=7)')) at 279 - check_search - /Users/truongthuan/Develop/python/blog/flashcard/search.py
 2021-03-26 20:37:22.854163 : HTTPSConnectionPool(host='www.oxfordlearnersdictionaries.com', port=443): Max retries exceeded with url: /definition/english/bureaucracy (Caused by ConnectTimeoutError(<urllib3.connection.HTTPSConnection object at 0x103886580>, 'Connection to 167.71.41.173 timed out. (connect timeout=7)')) at 279 - check_search - /Users/truongthuan/Develop/python/blog/flashcard/search.py
 2021-03-26 20:37:29.883677 : HTTPSConnectionPool(host='www.oxfordlearnersdictionaries.com', port=443): Max retries exceeded with url: /definition/english/bureaucracy (Caused by ConnectTimeoutError(<urllib3.connection.HTTPSConnection object at 0x10385ff40>, 'Connection to 179.53.220.156 timed out. (connect timeout=7)')) at 279 - check_search - /Users/truongthuan/Develop/python/blog/flashcard/search.py
 2021-03-26 20:37:36.889847 : HTTPSConnectionPool(host='www.oxfordlearnersdictionaries.com', port=443): Max retries exceeded with url: /definition/english/bureaucracy (Caused by ConnectTimeoutError(<urllib3.connection.HTTPSConnection object at 0x10385f820>, 'Connection to 149.125.150.250 timed out. (connect timeout=7)')) at 279 - check_search - /Users/truongthuan/Develop/python/blog/flashcard/search.py
 2021-03-26 20:37:37.415844 : HTTPSConnectionPool(host='www.oxfordlearnersdictionaries.com', port=443): Max retries exceeded with url: /definition/english/bureaucracy (Caused by ProxyError('Cannot connect to proxy.', NewConnectionError('<urllib3.connection.HTTPSConnection object at 0x10383fdf0>: Failed to establish a new connection: [Errno 61] Connection refused'))) at 279 - check_search - /Users/truongthuan/Develop/python/blog/flashcard/search.py
 2021-03-26 20:37:37.443640 : HTTPSConnectionPool(host='www.oxfordlearnersdictionaries.com', port=443): Max retries exceeded with url: /definition/english/bureaucracy (Caused by ProxyError('Cannot connect to proxy.', NewConnectionError('<urllib3.connection.HTTPSConnection object at 0x103886d90>: Failed to establish a new connection: [Errno 61] Connection refused'))) at 279 - check_search - /Users/truongthuan/Develop/python/blog/flashcard/search.py
 2021-03-26 20:37:44.529638 : HTTPSConnectionPool(host='www.oxfordlearnersdictionaries.com', port=443): Max retries exceeded with url: /definition/english/bureaucracy (Caused by ProxyError('Cannot connect to proxy.', timeout('timed out'))) at 279 - check_search - /Users/truongthuan/Develop/python/blog/flashcard/search.py
 2021-03-26 20:38:00.699918 : saved file bureaucracy+noun+us.mp3 at 56 - downloadFileFromUrl - /Users/truongthuan/Develop/python/blog/flashcard/helper.py
 2021-03-26 20:38:08.017894 : saved file bureaucracy+noun+uk.mp3 at 56 - downloadFileFromUrl - /Users/truongthuan/Develop/python/blog/flashcard/helper.py
 2021-03-26 20:38:08.031060 : Field 'id' expected a number but got (1,). at 279 - check_search - /Users/truongthuan/Develop/python/blog/flashcard/search.py
 2021-03-26 20:38:15.035429 : HTTPSConnectionPool(host='www.oxfordlearnersdictionaries.com', port=443): Max retries exceeded with url: /definition/english/bureaucracy (Caused by ConnectTimeoutError(<urllib3.connection.HTTPSConnection object at 0x103bcf5b0>, 'Connection to 191.242.178.209 timed out. (connect timeout=7)')) at 279 - check_search - /Users/truongthuan/Develop/python/blog/flashcard/search.py
 2021-03-26 20:38:22.076156 : HTTPSConnectionPool(host='www.oxfordlearnersdictionaries.com', port=443): Max retries exceeded with url: /definition/english/bureaucracy (Caused by ConnectTimeoutError(<urllib3.connection.HTTPSConnection object at 0x103bcfd90>, 'Connection to 208.80.28.208 timed out. (connect timeout=7)')) at 279 - check_search - /Users/truongthuan/Develop/python/blog/flashcard/search.py
 2021-03-26 20:38:29.471017 : HTTPSConnectionPool(host='www.oxfordlearnersdictionaries.com', port=443): Max retries exceeded with url: /definition/english/bureaucracy (Caused by ProxyError('Cannot connect to proxy.', timeout('timed out'))) at 279 - check_search - /Users/truongthuan/Develop/python/blog/flashcard/search.py
 2021-03-26 20:39:12.735129 : HTTPSConnectionPool(host='www.oxfordlearnersdictionaries.com', port=443): Max retries exceeded with url: /definition/english/bureaucracy (Caused by ProxyError('Cannot connect to proxy.', OSError('Tunnel connection failed: 503 Too many open connections'))) at 279 - check_search - /Users/truongthuan/Develop/python/blog/flashcard/search.py
 2021-03-26 20:39:19.744749 : HTTPSConnectionPool(host='www.oxfordlearnersdictionaries.com', port=443): Max retries exceeded with url: /definition/english/bureaucracy (Caused by ConnectTimeoutError(<urllib3.connection.HTTPSConnection object at 0x10906b760>, 'Connection to 178.112.5.135 timed out. (connect timeout=7)')) at 279 - check_search - /Users/truongthuan/Develop/python/blog/flashcard/search.py
 2021-03-26 20:39:36.140215 : HTTPSConnectionPool(host='www.oxfordlearnersdictionaries.com', port=443): Max retries exceeded with url: /definition/english/bureaucracy (Caused by ProxyError('Cannot connect to proxy.', OSError('Tunnel connection failed: 503 Too many open connections'))) at 279 - check_search - /Users/truongthuan/Develop/python/blog/flashcard/search.py
 2021-03-26 20:39:45.811709 : HTTPSConnectionPool(host='www.oxfordlearnersdictionaries.com', port=443): Max retries exceeded with url: /definition/english/bureaucracy (Caused by ProxyError('Cannot connect to proxy.', RemoteDisconnected('Remote end closed connection without response'))) at 279 - check_search - /Users/truongthuan/Develop/python/blog/flashcard/search.py
 2021-03-26 20:39:52.820518 : HTTPSConnectionPool(host='www.oxfordlearnersdictionaries.com', port=443): Max retries exceeded with url: /definition/english/bureaucracy (Caused by ConnectTimeoutError(<urllib3.connection.HTTPSConnection object at 0x1090956d0>, 'Connection to 178.112.5.135 timed out. (connect timeout=7)')) at 279 - check_search - /Users/truongthuan/Develop/python/blog/flashcard/search.py
 2021-03-26 20:39:56.152355 : HTTPSConnectionPool(host='www.oxfordlearnersdictionaries.com', port=443): Max retries exceeded with url: /definition/english/bureaucracy (Caused by ProxyError('Cannot connect to proxy.', OSError('Tunnel connection failed: 503 Too many open connections'))) at 279 - check_search - /Users/truongthuan/Develop/python/blog/flashcard/search.py
 2021-03-26 20:39:56.196785 : HTTPSConnectionPool(host='www.oxfordlearnersdictionaries.com', port=443): Max retries exceeded with url: /definition/english/bureaucracy (Caused by ProxyError('Cannot connect to proxy.', NewConnectionError('<urllib3.connection.HTTPSConnection object at 0x109095ee0>: Failed to establish a new connection: [Errno 61] Connection refused'))) at 279 - check_search - /Users/truongthuan/Develop/python/blog/flashcard/search.py
 2021-03-26 20:39:56.502201 : HTTPSConnectionPool(host='www.oxfordlearnersdictionaries.com', port=443): Max retries exceeded with url: /definition/english/bureaucracy (Caused by ProxyError('Cannot connect to proxy.', NewConnectionError('<urllib3.connection.HTTPSConnection object at 0x109095af0>: Failed to establish a new connection: [Errno 61] Connection refused'))) at 279 - check_search - /Users/truongthuan/Develop/python/blog/flashcard/search.py
 2021-03-26 20:39:57.585424 : HTTPSConnectionPool(host='www.oxfordlearnersdictionaries.com', port=443): Max retries exceeded with url: /definition/english/bureaucracy (Caused by ProxyError('Cannot connect to proxy.', OSError('Tunnel connection failed: 500 Internal Server Error'))) at 279 - check_search - /Users/truongthuan/Develop/python/blog/flashcard/search.py
 2021-03-26 20:39:58.733416 : HTTPSConnectionPool(host='www.oxfordlearnersdictionaries.com', port=443): Max retries exceeded with url: /definition/english/bureaucracy (Caused by ProxyError('Cannot connect to proxy.', OSError('Tunnel connection failed: 500 Internal Server Error'))) at 279 - check_search - /Users/truongthuan/Develop/python/blog/flashcard/search.py
 2021-03-26 20:40:16.942546 : saved file bureaucracy+noun+us.mp3 at 56 - downloadFileFromUrl - /Users/truongthuan/Develop/python/blog/flashcard/helper.py
 2021-03-26 20:40:23.291793 : saved file bureaucracy+noun+uk.mp3 at 56 - downloadFileFromUrl - /Users/truongthuan/Develop/python/blog/flashcard/helper.py
 2021-03-26 20:40:23.305525 : Saved <VocabularyCard: bureaucracy > successfully. at 216 - searchVocabulary - /Users/truongthuan/Develop/python/blog/flashcard/search.py
 2021-03-26 20:44:51.866593 : Searching vocabulary <<difficult>> at 324 - read_vocabulary_to_search - /Users/truongthuan/Develop/python/blog/flashcard/search.py
 2021-03-26 20:44:51.867447 : error: check_search() missing 1 required positional argument: 'topic' at <module> - /Users/truongthuan/Develop/python/blog/flashcard/search.py at 324 - read_vocabulary_to_search - /Users/truongthuan/Develop/python/blog/flashcard/search.py
 2021-03-26 20:45:14.509639 : Searching vocabulary <<difficult>> at 324 - read_vocabulary_to_search - /Users/truongthuan/Develop/python/blog/flashcard/search.py
 2021-03-26 20:45:21.540323 : HTTPSConnectionPool(host='www.oxfordlearnersdictionaries.com', port=443): Max retries exceeded with url: /definition/english/difficult (Caused by ConnectTimeoutError(<urllib3.connection.HTTPSConnection object at 0x10bd45280>, 'Connection to 191.242.178.209 timed out. (connect timeout=7)')) at 280 - check_search - /Users/truongthuan/Develop/python/blog/flashcard/search.py
 2021-03-26 20:45:22.458860 : HTTPSConnectionPool(host='www.oxfordlearnersdictionaries.com', port=443): Max retries exceeded with url: /definition/english/difficult (Caused by ProxyError('Cannot connect to proxy.', OSError('Tunnel connection failed: 500 Internal Server Error'))) at 280 - check_search - /Users/truongthuan/Develop/python/blog/flashcard/search.py
 2021-03-26 20:45:30.852316 : HTTPSConnectionPool(host='www.oxfordlearnersdictionaries.com', port=443): Max retries exceeded with url: /definition/english/difficult (Caused by ProxyError('Cannot connect to proxy.', timeout('timed out'))) at 280 - check_search - /Users/truongthuan/Develop/python/blog/flashcard/search.py
 2021-03-26 20:45:40.129724 : HTTPSConnectionPool(host='www.oxfordlearnersdictionaries.com', port=443): Max retries exceeded with url: /definition/english/difficult (Caused by ProxyError('Cannot connect to proxy.', timeout('_ssl.c:1106: The handshake operation timed out'))) at 280 - check_search - /Users/truongthuan/Develop/python/blog/flashcard/search.py
 2021-03-26 20:45:53.674899 : HTTPSConnectionPool(host='www.oxfordlearnersdictionaries.com', port=443): Read timed out. (read timeout=7) at 280 - check_search - /Users/truongthuan/Develop/python/blog/flashcard/search.py
 2021-03-26 20:46:00.705024 : HTTPSConnectionPool(host='www.oxfordlearnersdictionaries.com', port=443): Max retries exceeded with url: /definition/english/difficult (Caused by ConnectTimeoutError(<urllib3.connection.HTTPSConnection object at 0x10bdc0340>, 'Connection to 149.125.150.250 timed out. (connect timeout=7)')) at 280 - check_search - /Users/truongthuan/Develop/python/blog/flashcard/search.py
 2021-03-26 20:46:02.591387 : error: HTTPSConnectionPool(host='www.oxfordlearnersdictionaries.com', port=443): Max retries exceeded with url: /media/english/us_pron/d/dif/diffi/difficult__us_2_rr.mp3 (Caused by ProxyError('Cannot connect to proxy.', OSError('Tunnel connection failed: 500 Internal Server Error'))) at 56 - downloadFileFromUrl - /Users/truongthuan/Develop/python/blog/flashcard/helper.py
 2021-03-26 20:46:02.968947 : error: HTTPSConnectionPool(host='www.oxfordlearnersdictionaries.com', port=443): Max retries exceeded with url: /media/english/us_pron/d/dif/diffi/difficult__us_2_rr.mp3 (Caused by ProxyError('Cannot connect to proxy.', OSError('Tunnel connection failed: 500 Internal Server Error'))) at 56 - downloadFileFromUrl - /Users/truongthuan/Develop/python/blog/flashcard/helper.py
 2021-03-26 20:46:03.313763 : error: HTTPSConnectionPool(host='www.oxfordlearnersdictionaries.com', port=443): Max retries exceeded with url: /media/english/us_pron/d/dif/diffi/difficult__us_2_rr.mp3 (Caused by ProxyError('Cannot connect to proxy.', OSError('Tunnel connection failed: 500 Internal Server Error'))) at 56 - downloadFileFromUrl - /Users/truongthuan/Develop/python/blog/flashcard/helper.py
 2021-03-26 20:46:03.771144 : error: HTTPSConnectionPool(host='www.oxfordlearnersdictionaries.com', port=443): Max retries exceeded with url: /media/english/us_pron/d/dif/diffi/difficult__us_2_rr.mp3 (Caused by ProxyError('Cannot connect to proxy.', OSError('Tunnel connection failed: 500 Internal Server Error'))) at 56 - downloadFileFromUrl - /Users/truongthuan/Develop/python/blog/flashcard/helper.py
 2021-03-26 20:46:04.116516 : error: HTTPSConnectionPool(host='www.oxfordlearnersdictionaries.com', port=443): Max retries exceeded with url: /media/english/us_pron/d/dif/diffi/difficult__us_2_rr.mp3 (Caused by ProxyError('Cannot connect to proxy.', OSError('Tunnel connection failed: 500 Internal Server Error'))) at 56 - downloadFileFromUrl - /Users/truongthuan/Develop/python/blog/flashcard/helper.py
 2021-03-26 20:46:05.514606 : error: HTTPSConnectionPool(host='www.oxfordlearnersdictionaries.com', port=443): Max retries exceeded with url: /media/english/us_pron/d/dif/diffi/difficult__us_2_rr.mp3 (Caused by ProxyError('Cannot connect to proxy.', OSError('Tunnel connection failed: 500 Internal Server Error'))) at 56 - downloadFileFromUrl - /Users/truongthuan/Develop/python/blog/flashcard/helper.py
 2021-03-26 20:46:22.824647 : error: HTTPSConnectionPool(host='www.oxfordlearnersdictionaries.com', port=443): Max retries exceeded with url: /media/english/us_pron/d/dif/diffi/difficult__us_2_rr.mp3 (Caused by ProxyError('Cannot connect to proxy.', timeout('timed out'))) at 56 - downloadFileFromUrl - /Users/truongthuan/Develop/python/blog/flashcard/helper.py
 2021-03-26 20:46:37.975777 : saved file difficult+adjective+us.mp3 at 56 - downloadFileFromUrl - /Users/truongthuan/Develop/python/blog/flashcard/helper.py
 2021-03-26 20:46:38.377840 : error: HTTPSConnectionPool(host='www.oxfordlearnersdictionaries.com', port=443): Max retries exceeded with url: /media/english/uk_pron/d/dif/diffi/difficult__gb_2.mp3 (Caused by ProxyError('Cannot connect to proxy.', OSError('Tunnel connection failed: 500 Internal Server Error'))) at 56 - downloadFileFromUrl - /Users/truongthuan/Develop/python/blog/flashcard/helper.py
 2021-03-26 20:46:38.732554 : error: HTTPSConnectionPool(host='www.oxfordlearnersdictionaries.com', port=443): Max retries exceeded with url: /media/english/uk_pron/d/dif/diffi/difficult__gb_2.mp3 (Caused by ProxyError('Cannot connect to proxy.', OSError('Tunnel connection failed: 500 Internal Server Error'))) at 56 - downloadFileFromUrl - /Users/truongthuan/Develop/python/blog/flashcard/helper.py
 2021-03-26 20:46:39.210636 : error: HTTPSConnectionPool(host='www.oxfordlearnersdictionaries.com', port=443): Max retries exceeded with url: /media/english/uk_pron/d/dif/diffi/difficult__gb_2.mp3 (Caused by ProxyError('Cannot connect to proxy.', OSError('Tunnel connection failed: 500 Internal Server Error'))) at 56 - downloadFileFromUrl - /Users/truongthuan/Develop/python/blog/flashcard/helper.py
 2021-03-26 20:46:39.561692 : error: HTTPSConnectionPool(host='www.oxfordlearnersdictionaries.com', port=443): Max retries exceeded with url: /media/english/uk_pron/d/dif/diffi/difficult__gb_2.mp3 (Caused by ProxyError('Cannot connect to proxy.', OSError('Tunnel connection failed: 500 Internal Server Error'))) at 56 - downloadFileFromUrl - /Users/truongthuan/Develop/python/blog/flashcard/helper.py
 2021-03-26 20:46:40.122448 : error: HTTPSConnectionPool(host='www.oxfordlearnersdictionaries.com', port=443): Max retries exceeded with url: /media/english/uk_pron/d/dif/diffi/difficult__gb_2.mp3 (Caused by ProxyError('Cannot connect to proxy.', OSError('Tunnel connection failed: 500 Internal Server Error'))) at 56 - downloadFileFromUrl - /Users/truongthuan/Develop/python/blog/flashcard/helper.py
 2021-03-26 20:46:40.735935 : error: HTTPSConnectionPool(host='www.oxfordlearnersdictionaries.com', port=443): Max retries exceeded with url: /media/english/uk_pron/d/dif/diffi/difficult__gb_2.mp3 (Caused by ProxyError('Cannot connect to proxy.', OSError('Tunnel connection failed: 500 Internal Server Error'))) at 56 - downloadFileFromUrl - /Users/truongthuan/Develop/python/blog/flashcard/helper.py
 2021-03-26 20:46:57.742485 : error: HTTPSConnectionPool(host='www.oxfordlearnersdictionaries.com', port=443): Max retries exceeded with url: /media/english/uk_pron/d/dif/diffi/difficult__gb_2.mp3 (Caused by ConnectTimeoutError(<urllib3.connection.HTTPSConnection object at 0x10beea550>, 'Connection to 157.230.103.189 timed out. (connect timeout=17)')) at 56 - downloadFileFromUrl - /Users/truongthuan/Develop/python/blog/flashcard/helper.py
 2021-03-26 20:47:14.759941 : error: HTTPSConnectionPool(host='www.oxfordlearnersdictionaries.com', port=443): Max retries exceeded with url: /media/english/uk_pron/d/dif/diffi/difficult__gb_2.mp3 (Caused by ConnectTimeoutError(<urllib3.connection.HTTPSConnection object at 0x10beeac10>, 'Connection to 116.58.232.212 timed out. (connect timeout=17)')) at 56 - downloadFileFromUrl - /Users/truongthuan/Develop/python/blog/flashcard/helper.py
 2021-03-26 20:47:23.140825 : saved file difficult+adjective+uk.mp3 at 56 - downloadFileFromUrl - /Users/truongthuan/Develop/python/blog/flashcard/helper.py
 2021-03-26 20:47:23.158095 : Saved <VocabularyCard: difficult > successfully. at 217 - searchVocabulary - /Users/truongthuan/Develop/python/blog/flashcard/search.py
 2021-03-26 20:47:23.158402 : Searching vocabulary <<knowledge>> at 324 - read_vocabulary_to_search - /Users/truongthuan/Develop/python/blog/flashcard/search.py
 2021-03-26 20:47:23.536930 : HTTPSConnectionPool(host='www.oxfordlearnersdictionaries.com', port=443): Max retries exceeded with url: /definition/english/knowledge (Caused by ProxyError('Cannot connect to proxy.', NewConnectionError('<urllib3.connection.HTTPSConnection object at 0x10e1041c0>: Failed to establish a new connection: [Errno 61] Connection refused'))) at 280 - check_search - /Users/truongthuan/Develop/python/blog/flashcard/search.py
 2021-03-26 20:47:30.547335 : HTTPSConnectionPool(host='www.oxfordlearnersdictionaries.com', port=443): Max retries exceeded with url: /definition/english/knowledge (Caused by ConnectTimeoutError(<urllib3.connection.HTTPSConnection object at 0x10e104a00>, 'Connection to 149.125.150.250 timed out. (connect timeout=7)')) at 280 - check_search - /Users/truongthuan/Develop/python/blog/flashcard/search.py
 2021-03-26 20:47:41.598620 : HTTPSConnectionPool(host='www.oxfordlearnersdictionaries.com', port=443): Max retries exceeded with url: /definition/english/knowledge (Caused by ProxyError('Cannot connect to proxy.', timeout('timed out'))) at 280 - check_search - /Users/truongthuan/Develop/python/blog/flashcard/search.py
 2021-03-26 20:47:48.609858 : HTTPSConnectionPool(host='www.oxfordlearnersdictionaries.com', port=443): Max retries exceeded with url: /definition/english/knowledge (Caused by ConnectTimeoutError(<urllib3.connection.HTTPSConnection object at 0x10e110220>, 'Connection to 202.61.51.204 timed out. (connect timeout=7)')) at 280 - check_search - /Users/truongthuan/Develop/python/blog/flashcard/search.py
 2021-03-26 20:47:49.146707 : HTTPSConnectionPool(host='www.oxfordlearnersdictionaries.com', port=443): Max retries exceeded with url: /definition/english/knowledge (Caused by ProxyError('Cannot connect to proxy.', NewConnectionError('<urllib3.connection.HTTPSConnection object at 0x10e110a00>: Failed to establish a new connection: [Errno 61] Connection refused'))) at 280 - check_search - /Users/truongthuan/Develop/python/blog/flashcard/search.py
 2021-03-26 20:47:58.354006 : saved file knowledge+noun+us.mp3 at 56 - downloadFileFromUrl - /Users/truongthuan/Develop/python/blog/flashcard/helper.py
 2021-03-26 20:48:03.167918 : saved file knowledge+noun+uk.mp3 at 56 - downloadFileFromUrl - /Users/truongthuan/Develop/python/blog/flashcard/helper.py
 2021-03-26 20:48:03.171512 : Saved <VocabularyCard: knowledge > successfully. at 217 - searchVocabulary - /Users/truongthuan/Develop/python/blog/flashcard/search.py
 2021-03-26 20:48:03.173252 : error: name 'send_mail' is not defined at <module> - /Users/truongthuan/Develop/python/blog/flashcard/search.py at 324 - read_vocabulary_to_search - /Users/truongthuan/Develop/python/blog/flashcard/search.py
 2021-03-27 12:57:45.235527 : Searching vocabulary <<recognize>> at 325 - read_vocabulary_to_search - /Users/truongthuan/Develop/python/blog/flashcard/search.py
 2021-03-27 12:57:54.615004 : HTTPSConnectionPool(host='www.oxfordlearnersdictionaries.com', port=443): Max retries exceeded with url: /definition/english/recognize (Caused by ProxyError('Cannot connect to proxy.', timeout('timed out'))) at 281 - check_search - /Users/truongthuan/Develop/python/blog/flashcard/search.py
 2021-03-27 12:57:57.340623 : error: HTTPSConnectionPool(host='www.oxfordlearnersdictionaries.com', port=443): Max retries exceeded with url: /media/english/us_pron/r/rec/recog/recognize__us_3.mp3 (Caused by ProxyError('Cannot connect to proxy.', OSError('Tunnel connection failed: 503 Too many open connections'))) at 56 - downloadFileFromUrl - /Users/truongthuan/Develop/python/blog/flashcard/helper.py
 2021-03-27 12:57:57.955100 : error: HTTPSConnectionPool(host='www.oxfordlearnersdictionaries.com', port=443): Max retries exceeded with url: /media/english/us_pron/r/rec/recog/recognize__us_3.mp3 (Caused by ProxyError('Cannot connect to proxy.', OSError('Tunnel connection failed: 503 Too many open connections'))) at 56 - downloadFileFromUrl - /Users/truongthuan/Develop/python/blog/flashcard/helper.py
 2021-03-27 12:58:00.112930 : saved file recognize+verb+us.mp3 at 56 - downloadFileFromUrl - /Users/truongthuan/Develop/python/blog/flashcard/helper.py
 2021-03-27 12:58:02.770353 : saved file recognize+verb+uk.mp3 at 56 - downloadFileFromUrl - /Users/truongthuan/Develop/python/blog/flashcard/helper.py
 2021-03-27 12:58:02.858236 : Saved <VocabularyCard: recognize > successfully. at 218 - searchVocabulary - /Users/truongthuan/Develop/python/blog/flashcard/search.py
 2021-03-27 12:58:02.858568 : Searching vocabulary <<indicate>> at 325 - read_vocabulary_to_search - /Users/truongthuan/Develop/python/blog/flashcard/search.py
 2021-03-27 12:58:06.351880 : HTTPSConnectionPool(host='www.oxfordlearnersdictionaries.com', port=443): Max retries exceeded with url: /definition/english/indicate (Caused by ProxyError('Cannot connect to proxy.', RemoteDisconnected('Remote end closed connection without response'))) at 281 - check_search - /Users/truongthuan/Develop/python/blog/flashcard/search.py
 2021-03-27 12:58:11.089796 : saved file indicate+verb+us.mp3 at 56 - downloadFileFromUrl - /Users/truongthuan/Develop/python/blog/flashcard/helper.py
 2021-03-27 12:58:12.600994 : saved file indicate+verb+uk.mp3 at 56 - downloadFileFromUrl - /Users/truongthuan/Develop/python/blog/flashcard/helper.py
 2021-03-27 12:58:12.605016 : Saved <VocabularyCard: indicate > successfully. at 218 - searchVocabulary - /Users/truongthuan/Develop/python/blog/flashcard/search.py
 2021-03-27 13:04:05.512627 : Searching vocabulary <<interview>> at 325 - read_vocabulary_to_search - /Users/truongthuan/Develop/python/blog/flashcard/search.py
 2021-03-27 13:04:06.404909 : HTTPSConnectionPool(host='www.oxfordlearnersdictionaries.com', port=443): Max retries exceeded with url: /definition/english/interview (Caused by ProxyError('Cannot connect to proxy.', OSError('Tunnel connection failed: 500 Internal Server Error'))) at 281 - check_search - /Users/truongthuan/Develop/python/blog/flashcard/search.py
 2021-03-27 13:04:06.461663 : HTTPSConnectionPool(host='www.oxfordlearnersdictionaries.com', port=443): Max retries exceeded with url: /definition/english/interview (Caused by ProxyError('Cannot connect to proxy.', NewConnectionError('<urllib3.connection.HTTPSConnection object at 0x1049a32b0>: Failed to establish a new connection: [Errno 61] Connection refused'))) at 281 - check_search - /Users/truongthuan/Develop/python/blog/flashcard/search.py
 2021-03-27 13:04:13.471742 : HTTPSConnectionPool(host='www.oxfordlearnersdictionaries.com', port=443): Max retries exceeded with url: /definition/english/interview (Caused by ConnectTimeoutError(<urllib3.connection.HTTPSConnection object at 0x1049a3940>, 'Connection to 179.53.220.156 timed out. (connect timeout=7)')) at 281 - check_search - /Users/truongthuan/Develop/python/blog/flashcard/search.py
 2021-03-27 13:04:14.072315 : HTTPSConnectionPool(host='www.oxfordlearnersdictionaries.com', port=443): Max retries exceeded with url: /definition/english/interview (Caused by ProxyError('Cannot connect to proxy.', OSError('Tunnel connection failed: 503 Too many open connections'))) at 281 - check_search - /Users/truongthuan/Develop/python/blog/flashcard/search.py
 2021-03-27 13:04:38.758834 : error: HTTPSConnectionPool(host='www.oxfordlearnersdictionaries.com', port=443): Max retries exceeded with url: /media/english/us_pron/i/int/inter/interview__us_2.mp3 (Caused by ConnectTimeoutError(<urllib3.connection.HTTPSConnection object at 0x104b719d0>, 'Connection to 178.112.5.135 timed out. (connect timeout=17)')) at 56 - downloadFileFromUrl - /Users/truongthuan/Develop/python/blog/flashcard/helper.py
 2021-03-27 13:05:00.156837 : error: HTTPSConnectionPool(host='www.oxfordlearnersdictionaries.com', port=443): Max retries exceeded with url: /media/english/us_pron/i/int/inter/interview__us_2.mp3 (Caused by ProxyError('Cannot connect to proxy.', timeout('timed out'))) at 56 - downloadFileFromUrl - /Users/truongthuan/Develop/python/blog/flashcard/helper.py
 2021-03-27 13:05:18.171903 : saved file interview+noun+us.mp3 at 56 - downloadFileFromUrl - /Users/truongthuan/Develop/python/blog/flashcard/helper.py
 2021-03-27 13:05:22.370357 : saved file interview+noun+uk.mp3 at 56 - downloadFileFromUrl - /Users/truongthuan/Develop/python/blog/flashcard/helper.py
 2021-03-27 13:05:22.384879 : Saved <VocabularyCard: interview > successfully. at 218 - searchVocabulary - /Users/truongthuan/Develop/python/blog/flashcard/search.py
 2021-03-27 13:05:22.385205 : Searching vocabulary <<foundation>> at 325 - read_vocabulary_to_search - /Users/truongthuan/Develop/python/blog/flashcard/search.py
 2021-03-27 13:05:26.155680 : HTTPSConnectionPool(host='www.oxfordlearnersdictionaries.com', port=443): Max retries exceeded with url: /definition/english/foundation (Caused by SSLError(SSLCertVerificationError(1, '[SSL: CERTIFICATE_VERIFY_FAILED] certificate verify failed: self signed certificate in certificate chain (_ssl.c:1123)'))) at 281 - check_search - /Users/truongthuan/Develop/python/blog/flashcard/search.py
 2021-03-27 13:05:33.165341 : HTTPSConnectionPool(host='www.oxfordlearnersdictionaries.com', port=443): Max retries exceeded with url: /definition/english/foundation (Caused by ConnectTimeoutError(<urllib3.connection.HTTPSConnection object at 0x104ba3790>, 'Connection to 149.125.150.250 timed out. (connect timeout=7)')) at 281 - check_search - /Users/truongthuan/Develop/python/blog/flashcard/search.py
 2021-03-27 13:05:40.174263 : HTTPSConnectionPool(host='www.oxfordlearnersdictionaries.com', port=443): Max retries exceeded with url: /definition/english/foundation (Caused by ConnectTimeoutError(<urllib3.connection.HTTPSConnection object at 0x104ba3e50>, 'Connection to 103.227.254.118 timed out. (connect timeout=7)')) at 281 - check_search - /Users/truongthuan/Develop/python/blog/flashcard/search.py
 2021-03-27 13:05:40.797973 : HTTPSConnectionPool(host='www.oxfordlearnersdictionaries.com', port=443): Max retries exceeded with url: /definition/english/foundation (Caused by ProxyError('Cannot connect to proxy.', OSError('Tunnel connection failed: 503 Too many open connections'))) at 281 - check_search - /Users/truongthuan/Develop/python/blog/flashcard/search.py
 2021-03-27 13:05:44.999230 : saved file foundation+noun+us.mp3 at 56 - downloadFileFromUrl - /Users/truongthuan/Develop/python/blog/flashcard/helper.py
 2021-03-27 13:05:46.739134 : saved file foundation+noun+uk.mp3 at 56 - downloadFileFromUrl - /Users/truongthuan/Develop/python/blog/flashcard/helper.py
 2021-03-27 13:05:46.743223 : Saved <VocabularyCard: foundation > successfully. at 218 - searchVocabulary - /Users/truongthuan/Develop/python/blog/flashcard/search.py
 2021-03-27 13:05:46.743504 : Searching vocabulary <<quote>> at 325 - read_vocabulary_to_search - /Users/truongthuan/Develop/python/blog/flashcard/search.py
 2021-03-27 13:05:47.034595 : HTTPSConnectionPool(host='www.oxfordlearnersdictionaries.com', port=443): Max retries exceeded with url: /definition/english/quote (Caused by ProxyError('Cannot connect to proxy.', NewConnectionError('<urllib3.connection.HTTPSConnection object at 0x104cc09d0>: Failed to establish a new connection: [Errno 61] Connection refused'))) at 281 - check_search - /Users/truongthuan/Develop/python/blog/flashcard/search.py
 2021-03-27 13:05:47.069258 : HTTPSConnectionPool(host='www.oxfordlearnersdictionaries.com', port=443): Max retries exceeded with url: /definition/english/quote (Caused by ProxyError('Cannot connect to proxy.', NewConnectionError('<urllib3.connection.HTTPSConnection object at 0x104cc0eb0>: Failed to establish a new connection: [Errno 61] Connection refused'))) at 281 - check_search - /Users/truongthuan/Develop/python/blog/flashcard/search.py
 2021-03-27 13:05:47.453612 : HTTPSConnectionPool(host='www.oxfordlearnersdictionaries.com', port=443): Max retries exceeded with url: /definition/english/quote (Caused by ProxyError('Cannot connect to proxy.', NewConnectionError('<urllib3.connection.HTTPSConnection object at 0x104cc0e20>: Failed to establish a new connection: [Errno 61] Connection refused'))) at 281 - check_search - /Users/truongthuan/Develop/python/blog/flashcard/search.py
 2021-03-27 13:05:48.191449 : HTTPSConnectionPool(host='www.oxfordlearnersdictionaries.com', port=443): Max retries exceeded with url: /definition/english/quote (Caused by ProxyError('Cannot connect to proxy.', OSError('Tunnel connection failed: 503 Too many open connections'))) at 281 - check_search - /Users/truongthuan/Develop/python/blog/flashcard/search.py
 2021-03-27 13:05:51.650869 : HTTPSConnectionPool(host='www.oxfordlearnersdictionaries.com', port=443): Max retries exceeded with url: /definition/english/quote (Caused by SSLError(SSLCertVerificationError(1, '[SSL: CERTIFICATE_VERIFY_FAILED] certificate verify failed: self signed certificate in certificate chain (_ssl.c:1123)'))) at 281 - check_search - /Users/truongthuan/Develop/python/blog/flashcard/search.py
 2021-03-27 13:05:58.663434 : HTTPSConnectionPool(host='www.oxfordlearnersdictionaries.com', port=443): Max retries exceeded with url: /definition/english/quote (Caused by ConnectTimeoutError(<urllib3.connection.HTTPSConnection object at 0x104ccc820>, 'Connection to 178.112.5.135 timed out. (connect timeout=7)')) at 281 - check_search - /Users/truongthuan/Develop/python/blog/flashcard/search.py
 2021-03-27 13:06:05.674461 : HTTPSConnectionPool(host='www.oxfordlearnersdictionaries.com', port=443): Max retries exceeded with url: /definition/english/quote (Caused by ConnectTimeoutError(<urllib3.connection.HTTPSConnection object at 0x104cccdf0>, 'Connection to 208.80.28.208 timed out. (connect timeout=7)')) at 281 - check_search - /Users/truongthuan/Develop/python/blog/flashcard/search.py
 2021-03-27 13:06:06.293382 : HTTPSConnectionPool(host='www.oxfordlearnersdictionaries.com', port=443): Max retries exceeded with url: /definition/english/quote (Caused by ProxyError('Cannot connect to proxy.', OSError('Tunnel connection failed: 503 Too many open connections'))) at 281 - check_search - /Users/truongthuan/Develop/python/blog/flashcard/search.py
 2021-03-27 13:06:13.372960 : HTTPSConnectionPool(host='www.oxfordlearnersdictionaries.com', port=443): Max retries exceeded with url: /definition/english/quote (Caused by ProxyError('Cannot connect to proxy.', timeout('timed out'))) at 281 - check_search - /Users/truongthuan/Develop/python/blog/flashcard/search.py
 2021-03-27 13:06:20.940523 : HTTPSConnectionPool(host='www.oxfordlearnersdictionaries.com', port=443): Max retries exceeded with url: /definition/english/quote (Caused by ConnectTimeoutError(<urllib3.connection.HTTPSConnection object at 0x104ea9a60>, 'Connection to 45.231.75.35 timed out. (connect timeout=7)')) at 281 - check_search - /Users/truongthuan/Develop/python/blog/flashcard/search.py
 2021-03-27 13:06:21.241271 : HTTPSConnectionPool(host='www.oxfordlearnersdictionaries.com', port=443): Max retries exceeded with url: /definition/english/quote (Caused by ProxyError('Cannot connect to proxy.', NewConnectionError('<urllib3.connection.HTTPSConnection object at 0x104eb1280>: Failed to establish a new connection: [Errno 61] Connection refused'))) at 281 - check_search - /Users/truongthuan/Develop/python/blog/flashcard/search.py
 2021-03-27 13:06:27.286370 : saved file quote+verb+us.mp3 at 56 - downloadFileFromUrl - /Users/truongthuan/Develop/python/blog/flashcard/helper.py
 2021-03-27 13:06:29.745835 : saved file quote+verb+uk.mp3 at 56 - downloadFileFromUrl - /Users/truongthuan/Develop/python/blog/flashcard/helper.py
 2021-03-27 13:06:29.749757 : Saved <VocabularyCard: quote > successfully. at 218 - searchVocabulary - /Users/truongthuan/Develop/python/blog/flashcard/search.py
 2021-03-27 13:06:29.750043 : Searching vocabulary <<online>> at 325 - read_vocabulary_to_search - /Users/truongthuan/Develop/python/blog/flashcard/search.py
 2021-03-27 13:06:40.844543 : HTTPSConnectionPool(host='www.oxfordlearnersdictionaries.com', port=443): Read timed out. (read timeout=7) at 281 - check_search - /Users/truongthuan/Develop/python/blog/flashcard/search.py
 2021-03-27 13:06:47.870531 : HTTPSConnectionPool(host='www.oxfordlearnersdictionaries.com', port=443): Max retries exceeded with url: /definition/english/online (Caused by ConnectTimeoutError(<urllib3.connection.HTTPSConnection object at 0x104fc2040>, 'Connection to 192.46.228.240 timed out. (connect timeout=7)')) at 281 - check_search - /Users/truongthuan/Develop/python/blog/flashcard/search.py
 2021-03-27 13:06:48.451527 : HTTPSConnectionPool(host='www.oxfordlearnersdictionaries.com', port=443): Max retries exceeded with url: /definition/english/online (Caused by ProxyError('Cannot connect to proxy.', OSError('Tunnel connection failed: 503 Too many open connections'))) at 281 - check_search - /Users/truongthuan/Develop/python/blog/flashcard/search.py
 2021-03-27 13:06:55.458981 : HTTPSConnectionPool(host='www.oxfordlearnersdictionaries.com', port=443): Max retries exceeded with url: /definition/english/online (Caused by ConnectTimeoutError(<urllib3.connection.HTTPSConnection object at 0x104fc2880>, 'Connection to 192.46.228.240 timed out. (connect timeout=7)')) at 281 - check_search - /Users/truongthuan/Develop/python/blog/flashcard/search.py
 2021-03-27 13:06:55.928894 : HTTPSConnectionPool(host='www.oxfordlearnersdictionaries.com', port=443): Max retries exceeded with url: /definition/english/online (Caused by ProxyError('Cannot connect to proxy.', OSError('Tunnel connection failed: 500 Internal Server Error'))) at 281 - check_search - /Users/truongthuan/Develop/python/blog/flashcard/search.py
 2021-03-27 13:07:07.445215 : HTTPSConnectionPool(host='www.oxfordlearnersdictionaries.com', port=443): Max retries exceeded with url: /definition/english/online (Caused by ProxyError('Cannot connect to proxy.', timeout('timed out'))) at 281 - check_search - /Users/truongthuan/Develop/python/blog/flashcard/search.py
 2021-03-27 13:07:07.787370 : HTTPSConnectionPool(host='www.oxfordlearnersdictionaries.com', port=443): Max retries exceeded with url: /definition/english/online (Caused by ProxyError('Cannot connect to proxy.', OSError('Tunnel connection failed: 500 Internal Server Error'))) at 281 - check_search - /Users/truongthuan/Develop/python/blog/flashcard/search.py
 2021-03-27 13:07:14.186152 : saved file online+adjective+us.mp3 at 56 - downloadFileFromUrl - /Users/truongthuan/Develop/python/blog/flashcard/helper.py
 2021-03-27 13:07:16.667294 : saved file online+adjective+uk.mp3 at 56 - downloadFileFromUrl - /Users/truongthuan/Develop/python/blog/flashcard/helper.py
 2021-03-27 13:07:16.674247 : Saved <VocabularyCard: online > successfully. at 218 - searchVocabulary - /Users/truongthuan/Develop/python/blog/flashcard/search.py
 2021-03-27 13:07:16.675531 : Searching vocabulary <<pass>> at 325 - read_vocabulary_to_search - /Users/truongthuan/Develop/python/blog/flashcard/search.py
 2021-03-27 13:07:22.099449 : saved file pass+verb+us.mp3 at 56 - downloadFileFromUrl - /Users/truongthuan/Develop/python/blog/flashcard/helper.py
 2021-03-27 13:07:24.148153 : saved file pass+verb+uk.mp3 at 56 - downloadFileFromUrl - /Users/truongthuan/Develop/python/blog/flashcard/helper.py
 2021-03-27 13:07:24.152698 : Saved <VocabularyCard: pass > successfully. at 218 - searchVocabulary - /Users/truongthuan/Develop/python/blog/flashcard/search.py
 2021-03-27 13:07:24.152944 : Searching vocabulary <<negotiation>> at 325 - read_vocabulary_to_search - /Users/truongthuan/Develop/python/blog/flashcard/search.py
 2021-03-27 13:07:30.204334 : saved file negotiation+noun+us.mp3 at 56 - downloadFileFromUrl - /Users/truongthuan/Develop/python/blog/flashcard/helper.py
 2021-03-27 13:07:33.525554 : saved file negotiation+noun+uk.mp3 at 56 - downloadFileFromUrl - /Users/truongthuan/Develop/python/blog/flashcard/helper.py
 2021-03-27 13:07:33.529500 : Saved <VocabularyCard: negotiation > successfully. at 218 - searchVocabulary - /Users/truongthuan/Develop/python/blog/flashcard/search.py
 2021-03-27 13:07:33.529846 : Searching vocabulary <<good>> at 325 - read_vocabulary_to_search - /Users/truongthuan/Develop/python/blog/flashcard/search.py
 2021-03-27 13:07:38.069416 : HTTPSConnectionPool(host='www.oxfordlearnersdictionaries.com', port=443): Max retries exceeded with url: /definition/english/good (Caused by ProxyError('Cannot connect to proxy.', OSError('Tunnel connection failed: 500 Internal Server Error'))) at 281 - check_search - /Users/truongthuan/Develop/python/blog/flashcard/search.py
 2021-03-27 13:07:38.452544 : HTTPSConnectionPool(host='www.oxfordlearnersdictionaries.com', port=443): Max retries exceeded with url: /definition/english/good (Caused by ProxyError('Cannot connect to proxy.', OSError('Tunnel connection failed: 500 Internal Server Error'))) at 281 - check_search - /Users/truongthuan/Develop/python/blog/flashcard/search.py
 2021-03-27 13:07:45.462233 : HTTPSConnectionPool(host='www.oxfordlearnersdictionaries.com', port=443): Max retries exceeded with url: /definition/english/good (Caused by ConnectTimeoutError(<urllib3.connection.HTTPSConnection object at 0x1072dd0d0>, 'Connection to 191.242.178.209 timed out. (connect timeout=7)')) at 281 - check_search - /Users/truongthuan/Develop/python/blog/flashcard/search.py
 2021-03-27 13:07:51.644015 : saved file good+adjective+us.mp3 at 56 - downloadFileFromUrl - /Users/truongthuan/Develop/python/blog/flashcard/helper.py
 2021-03-27 13:07:52.966356 : saved file good+adjective+uk.mp3 at 56 - downloadFileFromUrl - /Users/truongthuan/Develop/python/blog/flashcard/helper.py
 2021-03-27 13:07:52.977328 : Saved <VocabularyCard: good > successfully. at 218 - searchVocabulary - /Users/truongthuan/Develop/python/blog/flashcard/search.py
 2021-03-27 13:07:52.977547 : Searching vocabulary <<urge>> at 325 - read_vocabulary_to_search - /Users/truongthuan/Develop/python/blog/flashcard/search.py
 2021-03-27 13:08:00.230569 : HTTPSConnectionPool(host='www.oxfordlearnersdictionaries.com', port=443): Max retries exceeded with url: /definition/english/urge (Caused by ProxyError('Cannot connect to proxy.', timeout('timed out'))) at 281 - check_search - /Users/truongthuan/Develop/python/blog/flashcard/search.py
 2021-03-27 13:08:07.241550 : HTTPSConnectionPool(host='www.oxfordlearnersdictionaries.com', port=443): Max retries exceeded with url: /definition/english/urge (Caused by ConnectTimeoutError(<urllib3.connection.HTTPSConnection object at 0x1072d5df0>, 'Connection to 149.125.150.250 timed out. (connect timeout=7)')) at 281 - check_search - /Users/truongthuan/Develop/python/blog/flashcard/search.py
 2021-03-27 13:08:16.591728 : HTTPSConnectionPool(host='www.oxfordlearnersdictionaries.com', port=443): Max retries exceeded with url: /definition/english/urge (Caused by ProxyError('Cannot connect to proxy.', timeout('timed out'))) at 281 - check_search - /Users/truongthuan/Develop/python/blog/flashcard/search.py
 2021-03-27 13:08:23.601878 : HTTPSConnectionPool(host='www.oxfordlearnersdictionaries.com', port=443): Max retries exceeded with url: /definition/english/urge (Caused by ConnectTimeoutError(<urllib3.connection.HTTPSConnection object at 0x107081a60>, 'Connection to 178.112.5.135 timed out. (connect timeout=7)')) at 281 - check_search - /Users/truongthuan/Develop/python/blog/flashcard/search.py
 2021-03-27 13:08:31.709288 : HTTPSConnectionPool(host='www.oxfordlearnersdictionaries.com', port=443): Max retries exceeded with url: /definition/english/urge (Caused by ProxyError('Cannot connect to proxy.', timeout('timed out'))) at 281 - check_search - /Users/truongthuan/Develop/python/blog/flashcard/search.py
 2021-03-27 13:08:40.930532 : saved file urge+verb+us.mp3 at 56 - downloadFileFromUrl - /Users/truongthuan/Develop/python/blog/flashcard/helper.py
 2021-03-27 13:08:42.412095 : saved file urge+verb+uk.mp3 at 56 - downloadFileFromUrl - /Users/truongthuan/Develop/python/blog/flashcard/helper.py
 2021-03-27 13:08:42.415727 : Saved <VocabularyCard: urge > successfully. at 218 - searchVocabulary - /Users/truongthuan/Develop/python/blog/flashcard/search.py
 2021-03-27 13:08:42.416083 : Searching vocabulary <<occasio>> at 325 - read_vocabulary_to_search - /Users/truongthuan/Develop/python/blog/flashcard/search.py
 2021-03-27 13:08:50.899744 : HTTPSConnectionPool(host='www.oxfordlearnersdictionaries.com', port=443): Max retries exceeded with url: /definition/english/occasio (Caused by ProxyError('Cannot connect to proxy.', timeout('_ssl.c:1106: The handshake operation timed out'))) at 281 - check_search - /Users/truongthuan/Develop/python/blog/flashcard/search.py
 2021-03-27 13:08:51.153670 : HTTPSConnectionPool(host='www.oxfordlearnersdictionaries.com', port=443): Max retries exceeded with url: /definition/english/occasio (Caused by ProxyError('Cannot connect to proxy.', NewConnectionError('<urllib3.connection.HTTPSConnection object at 0x107081eb0>: Failed to establish a new connection: [Errno 61] Connection refused'))) at 281 - check_search - /Users/truongthuan/Develop/python/blog/flashcard/search.py
 2021-03-27 13:08:51.424551 : HTTPSConnectionPool(host='www.oxfordlearnersdictionaries.com', port=443): Max retries exceeded with url: /definition/english/occasio (Caused by ProxyError('Cannot connect to proxy.', NewConnectionError('<urllib3.connection.HTTPSConnection object at 0x104cda7f0>: Failed to establish a new connection: [Errno 61] Connection refused'))) at 281 - check_search - /Users/truongthuan/Develop/python/blog/flashcard/search.py
 2021-03-27 13:08:58.797258 : list index out of range at 281 - check_search - /Users/truongthuan/Develop/python/blog/flashcard/search.py
 2021-03-27 13:08:59.142030 : HTTPSConnectionPool(host='www.oxfordlearnersdictionaries.com', port=443): Max retries exceeded with url: /definition/english/occasio (Caused by ProxyError('Cannot connect to proxy.', NewConnectionError('<urllib3.connection.HTTPSConnection object at 0x1070417c0>: Failed to establish a new connection: [Errno 61] Connection refused'))) at 281 - check_search - /Users/truongthuan/Develop/python/blog/flashcard/search.py
 2021-03-27 13:09:01.177355 : list index out of range at 281 - check_search - /Users/truongthuan/Develop/python/blog/flashcard/search.py
 2021-03-27 13:09:02.597825 : HTTPSConnectionPool(host='www.oxfordlearnersdictionaries.com', port=443): Max retries exceeded with url: /definition/english/occasio (Caused by ProxyError('Cannot connect to proxy.', OSError('Tunnel connection failed: 500 Internal Server Error'))) at 281 - check_search - /Users/truongthuan/Develop/python/blog/flashcard/search.py
 2021-03-27 13:09:09.603947 : HTTPSConnectionPool(host='www.oxfordlearnersdictionaries.com', port=443): Max retries exceeded with url: /definition/english/occasio (Caused by ConnectTimeoutError(<urllib3.connection.HTTPSConnection object at 0x104b22790>, 'Connection to 45.231.75.35 timed out. (connect timeout=7)')) at 281 - check_search - /Users/truongthuan/Develop/python/blog/flashcard/search.py
 2021-03-27 13:09:16.680068 : HTTPSConnectionPool(host='www.oxfordlearnersdictionaries.com', port=443): Max retries exceeded with url: /definition/english/occasio (Caused by ProxyError('Cannot connect to proxy.', timeout('timed out'))) at 281 - check_search - /Users/truongthuan/Develop/python/blog/flashcard/search.py
 2021-03-27 13:09:24.203381 : HTTPSConnectionPool(host='www.oxfordlearnersdictionaries.com', port=443): Max retries exceeded with url: /definition/english/occasio (Caused by ConnectTimeoutError(<urllib3.connection.HTTPSConnection object at 0x107010b80>, 'Connection to 191.242.178.209 timed out. (connect timeout=7)')) at 281 - check_search - /Users/truongthuan/Develop/python/blog/flashcard/search.py
 2021-03-27 13:09:27.671917 : list index out of range at 281 - check_search - /Users/truongthuan/Develop/python/blog/flashcard/search.py
 2021-03-27 13:09:36.667120 : list index out of range at 281 - check_search - /Users/truongthuan/Develop/python/blog/flashcard/search.py
 2021-03-27 13:09:43.949205 : HTTPSConnectionPool(host='www.oxfordlearnersdictionaries.com', port=443): Max retries exceeded with url: /definition/english/occasio (Caused by ProxyError('Cannot connect to proxy.', timeout('timed out'))) at 281 - check_search - /Users/truongthuan/Develop/python/blog/flashcard/search.py
 2021-03-27 13:09:52.332310 : list index out of range at 281 - check_search - /Users/truongthuan/Develop/python/blog/flashcard/search.py
 2021-03-27 13:09:52.360265 : HTTPSConnectionPool(host='www.oxfordlearnersdictionaries.com', port=443): Max retries exceeded with url: /definition/english/occasio (Caused by ProxyError('Cannot connect to proxy.', NewConnectionError('<urllib3.connection.HTTPSConnection object at 0x104cfeca0>: Failed to establish a new connection: [Errno 61] Connection refused'))) at 281 - check_search - /Users/truongthuan/Develop/python/blog/flashcard/search.py
 2021-03-27 13:09:59.368899 : HTTPSConnectionPool(host='www.oxfordlearnersdictionaries.com', port=443): Max retries exceeded with url: /definition/english/occasio (Caused by ConnectTimeoutError(<urllib3.connection.HTTPSConnection object at 0x104ce84c0>, 'Connection to 178.112.5.135 timed out. (connect timeout=7)')) at 281 - check_search - /Users/truongthuan/Develop/python/blog/flashcard/search.py
 2021-03-27 13:10:05.803492 : HTTPSConnectionPool(host='www.oxfordlearnersdictionaries.com', port=443): Max retries exceeded with url: /definition/english/occasio (Caused by SSLError(SSLCertVerificationError(1, '[SSL: CERTIFICATE_VERIFY_FAILED] certificate verify failed: self signed certificate in certificate chain (_ssl.c:1123)'))) at 281 - check_search - /Users/truongthuan/Develop/python/blog/flashcard/search.py
 2021-03-27 13:10:13.112612 : HTTPSConnectionPool(host='www.oxfordlearnersdictionaries.com', port=443): Max retries exceeded with url: /definition/english/occasio (Caused by ProxyError('Cannot connect to proxy.', timeout('timed out'))) at 281 - check_search - /Users/truongthuan/Develop/python/blog/flashcard/search.py
 2021-03-27 13:10:15.278766 : HTTPSConnectionPool(host='www.oxfordlearnersdictionaries.com', port=443): Max retries exceeded with url: /definition/english/occasio (Caused by ProxyError('Cannot connect to proxy.', OSError('Tunnel connection failed: 500 Internal Server Error'))) at 281 - check_search - /Users/truongthuan/Develop/python/blog/flashcard/search.py
 2021-03-27 13:10:22.284812 : HTTPSConnectionPool(host='www.oxfordlearnersdictionaries.com', port=443): Max retries exceeded with url: /definition/english/occasio (Caused by ConnectTimeoutError(<urllib3.connection.HTTPSConnection object at 0x104dab970>, 'Connection to 208.80.28.208 timed out. (connect timeout=7)')) at 281 - check_search - /Users/truongthuan/Develop/python/blog/flashcard/search.py
 2021-03-27 13:10:25.247808 : list index out of range at 281 - check_search - /Users/truongthuan/Develop/python/blog/flashcard/search.py
 2021-03-27 13:10:32.260933 : HTTPSConnectionPool(host='www.oxfordlearnersdictionaries.com', port=443): Max retries exceeded with url: /definition/english/occasio (Caused by ConnectTimeoutError(<urllib3.connection.HTTPSConnection object at 0x104d840d0>, 'Connection to 208.80.28.208 timed out. (connect timeout=7)')) at 281 - check_search - /Users/truongthuan/Develop/python/blog/flashcard/search.py
 2021-03-27 13:10:32.630765 : HTTPSConnectionPool(host='www.oxfordlearnersdictionaries.com', port=443): Max retries exceeded with url: /definition/english/occasio (Caused by ProxyError('Cannot connect to proxy.', NewConnectionError('<urllib3.connection.HTTPSConnection object at 0x104d848b0>: Failed to establish a new connection: [Errno 61] Connection refused'))) at 281 - check_search - /Users/truongthuan/Develop/python/blog/flashcard/search.py
 2021-03-27 13:10:32.981697 : HTTPSConnectionPool(host='www.oxfordlearnersdictionaries.com', port=443): Max retries exceeded with url: /definition/english/occasio (Caused by ProxyError('Cannot connect to proxy.', NewConnectionError('<urllib3.connection.HTTPSConnection object at 0x104dabd60>: Failed to establish a new connection: [Errno 61] Connection refused'))) at 281 - check_search - /Users/truongthuan/Develop/python/blog/flashcard/search.py
 2021-03-27 13:10:33.008360 : HTTPSConnectionPool(host='www.oxfordlearnersdictionaries.com', port=443): Max retries exceeded with url: /definition/english/occasio (Caused by ProxyError('Cannot connect to proxy.', NewConnectionError('<urllib3.connection.HTTPSConnection object at 0x104d846a0>: Failed to establish a new connection: [Errno 61] Connection refused'))) at 281 - check_search - /Users/truongthuan/Develop/python/blog/flashcard/search.py
 2021-03-27 13:10:40.018734 : HTTPSConnectionPool(host='www.oxfordlearnersdictionaries.com', port=443): Max retries exceeded with url: /definition/english/occasio (Caused by ConnectTimeoutError(<urllib3.connection.HTTPSConnection object at 0x104d8f0d0>, 'Connection to 179.53.220.156 timed out. (connect timeout=7)')) at 281 - check_search - /Users/truongthuan/Develop/python/blog/flashcard/search.py
 2021-03-27 13:10:51.405250 : HTTPSConnectionPool(host='www.oxfordlearnersdictionaries.com', port=443): Max retries exceeded with url: /definition/english/occasio (Caused by ProxyError('Cannot connect to proxy.', timeout('timed out'))) at 281 - check_search - /Users/truongthuan/Develop/python/blog/flashcard/search.py
 2021-03-27 13:10:51.407345 : Break search <<occasio>> at 281 - check_search - /Users/truongthuan/Develop/python/blog/flashcard/search.py
 2021-03-27 13:19:07.998637 : Searching vocabulary <<trouble>> at 325 - read_vocabulary_to_search - /Users/truongthuan/Develop/python/blog/flashcard/search.py
 2021-03-27 13:19:15.024773 : HTTPSConnectionPool(host='www.oxfordlearnersdictionaries.com', port=443): Max retries exceeded with url: /definition/english/trouble (Caused by ConnectTimeoutError(<urllib3.connection.HTTPSConnection object at 0x10c962c40>, 'Connection to 149.125.150.250 timed out. (connect timeout=7)')) at 281 - check_search - /Users/truongthuan/Develop/python/blog/flashcard/search.py
 2021-03-27 13:19:22.035517 : HTTPSConnectionPool(host='www.oxfordlearnersdictionaries.com', port=443): Max retries exceeded with url: /definition/english/trouble (Caused by ConnectTimeoutError(<urllib3.connection.HTTPSConnection object at 0x10c961dc0>, 'Connection to 149.125.150.250 timed out. (connect timeout=7)')) at 281 - check_search - /Users/truongthuan/Develop/python/blog/flashcard/search.py
 2021-03-27 13:19:23.397803 : HTTPSConnectionPool(host='www.oxfordlearnersdictionaries.com', port=443): Max retries exceeded with url: /definition/english/trouble (Caused by ProxyError('Cannot connect to proxy.', NewConnectionError('<urllib3.connection.HTTPSConnection object at 0x10c961160>: Failed to establish a new connection: [Errno 61] Connection refused'))) at 281 - check_search - /Users/truongthuan/Develop/python/blog/flashcard/search.py
 2021-03-27 13:19:30.411550 : HTTPSConnectionPool(host='www.oxfordlearnersdictionaries.com', port=443): Max retries exceeded with url: /definition/english/trouble (Caused by ConnectTimeoutError(<urllib3.connection.HTTPSConnection object at 0x10c9612b0>, 'Connection to 139.162.169.174 timed out. (connect timeout=7)')) at 281 - check_search - /Users/truongthuan/Develop/python/blog/flashcard/search.py
 2021-03-27 13:19:30.974965 : HTTPSConnectionPool(host='www.oxfordlearnersdictionaries.com', port=443): Max retries exceeded with url: /definition/english/trouble (Caused by ProxyError('Cannot connect to proxy.', OSError('Tunnel connection failed: 503 Too many open connections'))) at 281 - check_search - /Users/truongthuan/Develop/python/blog/flashcard/search.py
 2021-03-27 13:19:31.005090 : HTTPSConnectionPool(host='www.oxfordlearnersdictionaries.com', port=443): Max retries exceeded with url: /definition/english/trouble (Caused by ProxyError('Cannot connect to proxy.', NewConnectionError('<urllib3.connection.HTTPSConnection object at 0x10c9617c0>: Failed to establish a new connection: [Errno 61] Connection refused'))) at 281 - check_search - /Users/truongthuan/Develop/python/blog/flashcard/search.py
 2021-03-27 13:19:31.033805 : HTTPSConnectionPool(host='www.oxfordlearnersdictionaries.com', port=443): Max retries exceeded with url: /definition/english/trouble (Caused by ProxyError('Cannot connect to proxy.', NewConnectionError('<urllib3.connection.HTTPSConnection object at 0x10c962430>: Failed to establish a new connection: [Errno 61] Connection refused'))) at 281 - check_search - /Users/truongthuan/Develop/python/blog/flashcard/search.py
 2021-03-27 13:19:38.044273 : HTTPSConnectionPool(host='www.oxfordlearnersdictionaries.com', port=443): Max retries exceeded with url: /definition/english/trouble (Caused by ConnectTimeoutError(<urllib3.connection.HTTPSConnection object at 0x10c95d8e0>, 'Connection to 178.112.5.135 timed out. (connect timeout=7)')) at 281 - check_search - /Users/truongthuan/Develop/python/blog/flashcard/search.py
 2021-03-27 13:19:50.367633 : HTTPSConnectionPool(host='www.oxfordlearnersdictionaries.com', port=443): Max retries exceeded with url: /definition/english/trouble (Caused by ProxyError('Cannot connect to proxy.', timeout('timed out'))) at 281 - check_search - /Users/truongthuan/Develop/python/blog/flashcard/search.py
 2021-03-27 13:19:58.910129 : HTTPSConnectionPool(host='www.oxfordlearnersdictionaries.com', port=443): Max retries exceeded with url: /definition/english/trouble (Caused by ConnectTimeoutError(<urllib3.connection.HTTPSConnection object at 0x10cbe4f10>, 'Connection to 192.46.228.240 timed out. (connect timeout=7)')) at 281 - check_search - /Users/truongthuan/Develop/python/blog/flashcard/search.py
 2021-03-27 13:20:06.238051 : HTTPSConnectionPool(host='www.oxfordlearnersdictionaries.com', port=443): Max retries exceeded with url: /definition/english/trouble (Caused by ProxyError('Cannot connect to proxy.', timeout('timed out'))) at 281 - check_search - /Users/truongthuan/Develop/python/blog/flashcard/search.py
 2021-03-27 13:20:13.613249 : HTTPSConnectionPool(host='www.oxfordlearnersdictionaries.com', port=443): Max retries exceeded with url: /definition/english/trouble (Caused by ProxyError('Cannot connect to proxy.', timeout('timed out'))) at 281 - check_search - /Users/truongthuan/Develop/python/blog/flashcard/search.py
 2021-03-27 13:20:20.632296 : HTTPSConnectionPool(host='www.oxfordlearnersdictionaries.com', port=443): Max retries exceeded with url: /definition/english/trouble (Caused by ConnectTimeoutError(<urllib3.connection.HTTPSConnection object at 0x10cbf6940>, 'Connection to 208.80.28.208 timed out. (connect timeout=7)')) at 281 - check_search - /Users/truongthuan/Develop/python/blog/flashcard/search.py
 2021-03-27 13:20:26.778695 : HTTPSConnectionPool(host='www.oxfordlearnersdictionaries.com', port=443): Max retries exceeded with url: /definition/english/trouble (Caused by SSLError(SSLCertVerificationError(1, '[SSL: CERTIFICATE_VERIFY_FAILED] certificate verify failed: self signed certificate in certificate chain (_ssl.c:1123)'))) at 281 - check_search - /Users/truongthuan/Develop/python/blog/flashcard/search.py
 2021-03-27 13:20:33.788451 : HTTPSConnectionPool(host='www.oxfordlearnersdictionaries.com', port=443): Max retries exceeded with url: /definition/english/trouble (Caused by ConnectTimeoutError(<urllib3.connection.HTTPSConnection object at 0x10c95b130>, 'Connection to 192.46.228.240 timed out. (connect timeout=7)')) at 281 - check_search - /Users/truongthuan/Develop/python/blog/flashcard/search.py
 2021-03-27 13:20:40.803932 : HTTPSConnectionPool(host='www.oxfordlearnersdictionaries.com', port=443): Max retries exceeded with url: /definition/english/trouble (Caused by ConnectTimeoutError(<urllib3.connection.HTTPSConnection object at 0x10cbf6280>, 'Connection to 208.80.28.208 timed out. (connect timeout=7)')) at 281 - check_search - /Users/truongthuan/Develop/python/blog/flashcard/search.py
 2021-03-27 13:20:49.101249 : HTTPSConnectionPool(host='www.oxfordlearnersdictionaries.com', port=443): Max retries exceeded with url: /definition/english/trouble (Caused by ProxyError('Cannot connect to proxy.', OSError('Tunnel connection failed: 503 Service Unavailable'))) at 281 - check_search - /Users/truongthuan/Develop/python/blog/flashcard/search.py
 2021-03-27 13:20:51.966634 : HTTPSConnectionPool(host='www.oxfordlearnersdictionaries.com', port=443): Max retries exceeded with url: /definition/english/trouble (Caused by ProxyError('Cannot connect to proxy.', OSError('Tunnel connection failed: 503 Service Unavailable'))) at 281 - check_search - /Users/truongthuan/Develop/python/blog/flashcard/search.py
 2021-03-27 13:21:06.460398 : HTTPSConnectionPool(host='www.oxfordlearnersdictionaries.com', port=443): Read timed out. (read timeout=7) at 281 - check_search - /Users/truongthuan/Develop/python/blog/flashcard/search.py
 2021-03-27 13:21:13.467538 : HTTPSConnectionPool(host='www.oxfordlearnersdictionaries.com', port=443): Max retries exceeded with url: /definition/english/trouble (Caused by ConnectTimeoutError(<urllib3.connection.HTTPSConnection object at 0x10cde6040>, 'Connection to 191.242.178.209 timed out. (connect timeout=7)')) at 281 - check_search - /Users/truongthuan/Develop/python/blog/flashcard/search.py
 2021-03-27 13:21:23.356118 : HTTPSConnectionPool(host='www.oxfordlearnersdictionaries.com', port=443): Max retries exceeded with url: /definition/english/trouble (Caused by ProxyError('Cannot connect to proxy.', timeout('_ssl.c:1106: The handshake operation timed out'))) at 281 - check_search - /Users/truongthuan/Develop/python/blog/flashcard/search.py
 2021-03-27 13:21:30.363874 : HTTPSConnectionPool(host='www.oxfordlearnersdictionaries.com', port=443): Max retries exceeded with url: /definition/english/trouble (Caused by ConnectTimeoutError(<urllib3.connection.HTTPSConnection object at 0x10cde6970>, 'Connection to 192.46.228.240 timed out. (connect timeout=7)')) at 281 - check_search - /Users/truongthuan/Develop/python/blog/flashcard/search.py
 2021-03-27 13:21:43.682049 : saved file trouble+noun+us.mp3 at 58 - downloadFileFromUrl - /Users/truongthuan/Develop/python/blog/flashcard/helper.py
 2021-03-27 13:21:47.982902 : saved file trouble+noun+uk.mp3 at 58 - downloadFileFromUrl - /Users/truongthuan/Develop/python/blog/flashcard/helper.py
 2021-03-27 13:21:48.002004 : Saved <VocabularyCard: trouble > successfully. at 218 - searchVocabulary - /Users/truongthuan/Develop/python/blog/flashcard/search.py
 2021-03-27 13:21:48.002221 : Searching vocabulary <<necessary>> at 325 - read_vocabulary_to_search - /Users/truongthuan/Develop/python/blog/flashcard/search.py
 2021-03-27 13:21:55.009884 : HTTPSConnectionPool(host='www.oxfordlearnersdictionaries.com', port=443): Max retries exceeded with url: /definition/english/necessary (Caused by ConnectTimeoutError(<urllib3.connection.HTTPSConnection object at 0x10cf6bc70>, 'Connection to 103.227.254.118 timed out. (connect timeout=7)')) at 281 - check_search - /Users/truongthuan/Develop/python/blog/flashcard/search.py
 2021-03-27 13:21:55.455632 : HTTPSConnectionPool(host='www.oxfordlearnersdictionaries.com', port=443): Max retries exceeded with url: /definition/english/necessary (Caused by ProxyError('Cannot connect to proxy.', NewConnectionError('<urllib3.connection.HTTPSConnection object at 0x10cf8d4f0>: Failed to establish a new connection: [Errno 61] Connection refused'))) at 281 - check_search - /Users/truongthuan/Develop/python/blog/flashcard/search.py
 2021-03-27 13:21:55.760898 : HTTPSConnectionPool(host='www.oxfordlearnersdictionaries.com', port=443): Max retries exceeded with url: /definition/english/necessary (Caused by ProxyError('Cannot connect to proxy.', NewConnectionError('<urllib3.connection.HTTPSConnection object at 0x10cf8dcd0>: Failed to establish a new connection: [Errno 61] Connection refused'))) at 281 - check_search - /Users/truongthuan/Develop/python/blog/flashcard/search.py
 2021-03-27 13:21:56.682800 : HTTPSConnectionPool(host='www.oxfordlearnersdictionaries.com', port=443): Max retries exceeded with url: /definition/english/necessary (Caused by ProxyError('Cannot connect to proxy.', OSError('Tunnel connection failed: 503 Too many open connections'))) at 281 - check_search - /Users/truongthuan/Develop/python/blog/flashcard/search.py
 2021-03-27 13:21:58.877771 : HTTPSConnectionPool(host='www.oxfordlearnersdictionaries.com', port=443): Max retries exceeded with url: /definition/english/necessary (Caused by ProxyError('Cannot connect to proxy.', OSError('Tunnel connection failed: 503 Too many open connections'))) at 281 - check_search - /Users/truongthuan/Develop/python/blog/flashcard/search.py
 2021-03-27 13:22:06.615993 : HTTPSConnectionPool(host='www.oxfordlearnersdictionaries.com', port=443): Max retries exceeded with url: /definition/english/necessary (Caused by SSLError(SSLCertVerificationError(1, '[SSL: CERTIFICATE_VERIFY_FAILED] certificate verify failed: self signed certificate in certificate chain (_ssl.c:1123)'))) at 281 - check_search - /Users/truongthuan/Develop/python/blog/flashcard/search.py
 2021-03-27 13:22:08.955216 : HTTPSConnectionPool(host='www.oxfordlearnersdictionaries.com', port=443): Max retries exceeded with url: /definition/english/necessary (Caused by ProxyError('Cannot connect to proxy.', OSError('Tunnel connection failed: 503 Too many open connections'))) at 281 - check_search - /Users/truongthuan/Develop/python/blog/flashcard/search.py
 2021-03-27 13:22:15.962650 : HTTPSConnectionPool(host='www.oxfordlearnersdictionaries.com', port=443): Max retries exceeded with url: /definition/english/necessary (Caused by ConnectTimeoutError(<urllib3.connection.HTTPSConnection object at 0x10cf95490>, 'Connection to 103.227.254.118 timed out. (connect timeout=7)')) at 281 - check_search - /Users/truongthuan/Develop/python/blog/flashcard/search.py
 2021-03-27 13:22:22.592962 : saved file necessary+adjective+us.mp3 at 58 - downloadFileFromUrl - /Users/truongthuan/Develop/python/blog/flashcard/helper.py
 2021-03-27 13:22:25.870363 : saved file necessary+adjective+uk.mp3 at 58 - downloadFileFromUrl - /Users/truongthuan/Develop/python/blog/flashcard/helper.py
 2021-03-27 13:22:25.874145 : Saved <VocabularyCard: necessary > successfully. at 218 - searchVocabulary - /Users/truongthuan/Develop/python/blog/flashcard/search.py
 2021-03-27 13:22:25.874528 : Searching vocabulary <<throughout>> at 325 - read_vocabulary_to_search - /Users/truongthuan/Develop/python/blog/flashcard/search.py
 2021-03-27 13:22:36.962496 : HTTPSConnectionPool(host='www.oxfordlearnersdictionaries.com', port=443): Max retries exceeded with url: /definition/english/throughout (Caused by ProxyError('Cannot connect to proxy.', timeout('timed out'))) at 281 - check_search - /Users/truongthuan/Develop/python/blog/flashcard/search.py
 2021-03-27 13:22:37.008956 : HTTPSConnectionPool(host='www.oxfordlearnersdictionaries.com', port=443): Max retries exceeded with url: /definition/english/throughout (Caused by ProxyError('Cannot connect to proxy.', NewConnectionError('<urllib3.connection.HTTPSConnection object at 0x10f06a850>: Failed to establish a new connection: [Errno 61] Connection refused'))) at 281 - check_search - /Users/truongthuan/Develop/python/blog/flashcard/search.py
 2021-03-27 13:22:45.123198 : HTTPSConnectionPool(host='www.oxfordlearnersdictionaries.com', port=443): Max retries exceeded with url: /definition/english/throughout (Caused by ProxyError('Cannot connect to proxy.', timeout('timed out'))) at 281 - check_search - /Users/truongthuan/Develop/python/blog/flashcard/search.py
 2021-03-27 13:22:52.130268 : HTTPSConnectionPool(host='www.oxfordlearnersdictionaries.com', port=443): Max retries exceeded with url: /definition/english/throughout (Caused by ConnectTimeoutError(<urllib3.connection.HTTPSConnection object at 0x10f06aeb0>, 'Connection to 208.80.28.208 timed out. (connect timeout=7)')) at 281 - check_search - /Users/truongthuan/Develop/python/blog/flashcard/search.py
 2021-03-27 13:22:55.873461 : saved file throughout+preposition, adverb+us.mp3 at 58 - downloadFileFromUrl - /Users/truongthuan/Develop/python/blog/flashcard/helper.py
 2021-03-27 13:22:57.774551 : saved file throughout+preposition, adverb+uk.mp3 at 58 - downloadFileFromUrl - /Users/truongthuan/Develop/python/blog/flashcard/helper.py
 2021-03-27 13:22:57.778348 : Saved <VocabularyCard: throughout > successfully. at 218 - searchVocabulary - /Users/truongthuan/Develop/python/blog/flashcard/search.py
 2021-03-27 13:22:57.778705 : Searching vocabulary <<challenge>> at 325 - read_vocabulary_to_search - /Users/truongthuan/Develop/python/blog/flashcard/search.py
 2021-03-27 13:22:57.828038 : HTTPSConnectionPool(host='www.oxfordlearnersdictionaries.com', port=443): Max retries exceeded with url: /definition/english/challenge (Caused by ProxyError('Cannot connect to proxy.', NewConnectionError('<urllib3.connection.HTTPSConnection object at 0x10f000cd0>: Failed to establish a new connection: [Errno 61] Connection refused'))) at 281 - check_search - /Users/truongthuan/Develop/python/blog/flashcard/search.py
 2021-03-27 13:23:05.295079 : saved file challenge+noun+us.mp3 at 58 - downloadFileFromUrl - /Users/truongthuan/Develop/python/blog/flashcard/helper.py
 2021-03-27 13:23:07.751399 : saved file challenge+noun+uk.mp3 at 58 - downloadFileFromUrl - /Users/truongthuan/Develop/python/blog/flashcard/helper.py
 2021-03-27 13:23:07.755288 : Saved <VocabularyCard: challenge > successfully. at 218 - searchVocabulary - /Users/truongthuan/Develop/python/blog/flashcard/search.py
 2021-03-27 13:27:54.017492 : Searching vocabulary <<conduct>> at 333 - read_vocabulary_to_search - /Users/truongthuan/Develop/python/blog/flashcard/search.py
 2021-03-27 13:28:01.045878 : HTTPSConnectionPool(host='www.oxfordlearnersdictionaries.com', port=443): Max retries exceeded with url: /definition/english/conduct (Caused by ConnectTimeoutError(<urllib3.connection.HTTPSConnection object at 0x110c88070>, 'Connection to 192.46.228.240 timed out. (connect timeout=7)')) at 289 - check_search - /Users/truongthuan/Develop/python/blog/flashcard/search.py
 2021-03-27 13:28:08.337878 : HTTPSConnectionPool(host='www.oxfordlearnersdictionaries.com', port=443): Max retries exceeded with url: /definition/english/conduct (Caused by ProxyError('Cannot connect to proxy.', timeout('timed out'))) at 289 - check_search - /Users/truongthuan/Develop/python/blog/flashcard/search.py
 2021-03-27 13:28:15.348978 : HTTPSConnectionPool(host='www.oxfordlearnersdictionaries.com', port=443): Max retries exceeded with url: /definition/english/conduct (Caused by ConnectTimeoutError(<urllib3.connection.HTTPSConnection object at 0x110c88970>, 'Connection to 149.125.150.250 timed out. (connect timeout=7)')) at 289 - check_search - /Users/truongthuan/Develop/python/blog/flashcard/search.py
 2021-03-27 13:28:22.641588 : saved file conduct+verb+us.mp3 at 58 - downloadFileFromUrl - /Users/truongthuan/Develop/python/blog/flashcard/helper.py
 2021-03-27 13:28:25.505507 : saved file conduct+verb+uk.mp3 at 58 - downloadFileFromUrl - /Users/truongthuan/Develop/python/blog/flashcard/helper.py
 2021-03-27 13:28:25.528011 : Saved <VocabularyCard: conduct > successfully. at 226 - searchVocabulary - /Users/truongthuan/Develop/python/blog/flashcard/search.py
 2021-03-27 13:28:25.528368 : Searching vocabulary <<announce>> at 333 - read_vocabulary_to_search - /Users/truongthuan/Develop/python/blog/flashcard/search.py
 2021-03-27 13:28:46.198156 : saved file announce+verb+us.mp3 at 58 - downloadFileFromUrl - /Users/truongthuan/Develop/python/blog/flashcard/helper.py
 2021-03-27 13:28:55.913849 : error: HTTPSConnectionPool(host='www.oxfordlearnersdictionaries.com', port=443): Max retries exceeded with url: /media/english/uk_pron/a/ann/annou/announce__gb_1.mp3 (Caused by ProxyError('Cannot connect to proxy.', RemoteDisconnected('Remote end closed connection without response'))) at 58 - downloadFileFromUrl - /Users/truongthuan/Develop/python/blog/flashcard/helper.py
 2021-03-27 13:29:04.411747 : error: HTTPSConnectionPool(host='www.oxfordlearnersdictionaries.com', port=443): Max retries exceeded with url: /media/english/uk_pron/a/ann/annou/announce__gb_1.mp3 (Caused by ProxyError('Cannot connect to proxy.', OSError('Tunnel connection failed: 503 Too many open connections'))) at 58 - downloadFileFromUrl - /Users/truongthuan/Develop/python/blog/flashcard/helper.py
 2021-03-27 13:29:14.449455 : saved file announce+verb+uk.mp3 at 58 - downloadFileFromUrl - /Users/truongthuan/Develop/python/blog/flashcard/helper.py
 2021-03-27 13:29:14.457799 : Saved <VocabularyCard: announce > successfully. at 226 - searchVocabulary - /Users/truongthuan/Develop/python/blog/flashcard/search.py
 2021-03-27 13:29:14.458083 : Searching vocabulary <<conversation>> at 333 - read_vocabulary_to_search - /Users/truongthuan/Develop/python/blog/flashcard/search.py
 2021-03-27 13:29:21.468315 : HTTPSConnectionPool(host='www.oxfordlearnersdictionaries.com', port=443): Max retries exceeded with url: /definition/english/conversation (Caused by ConnectTimeoutError(<urllib3.connection.HTTPSConnection object at 0x110f6c130>, 'Connection to 208.80.28.208 timed out. (connect timeout=7)')) at 289 - check_search - /Users/truongthuan/Develop/python/blog/flashcard/search.py
 2021-03-27 13:29:25.433813 : HTTPSConnectionPool(host='www.oxfordlearnersdictionaries.com', port=443): Max retries exceeded with url: /definition/english/conversation (Caused by ProxyError('Cannot connect to proxy.', OSError('Tunnel connection failed: 503 Service Unavailable'))) at 289 - check_search - /Users/truongthuan/Develop/python/blog/flashcard/search.py
 2021-03-27 13:29:32.444685 : HTTPSConnectionPool(host='www.oxfordlearnersdictionaries.com', port=443): Max retries exceeded with url: /definition/english/conversation (Caused by ConnectTimeoutError(<urllib3.connection.HTTPSConnection object at 0x110f6ca90>, 'Connection to 149.125.150.250 timed out. (connect timeout=7)')) at 289 - check_search - /Users/truongthuan/Develop/python/blog/flashcard/search.py
 2021-03-27 13:29:33.184500 : HTTPSConnectionPool(host='www.oxfordlearnersdictionaries.com', port=443): Max retries exceeded with url: /definition/english/conversation (Caused by ProxyError('Cannot connect to proxy.', OSError('Tunnel connection failed: 500 Internal Server Error'))) at 289 - check_search - /Users/truongthuan/Develop/python/blog/flashcard/search.py
 2021-03-27 13:29:40.190891 : HTTPSConnectionPool(host='www.oxfordlearnersdictionaries.com', port=443): Max retries exceeded with url: /definition/english/conversation (Caused by ConnectTimeoutError(<urllib3.connection.HTTPSConnection object at 0x110f70160>, 'Connection to 149.125.150.250 timed out. (connect timeout=7)')) at 289 - check_search - /Users/truongthuan/Develop/python/blog/flashcard/search.py
 2021-03-27 13:29:47.202334 : HTTPSConnectionPool(host='www.oxfordlearnersdictionaries.com', port=443): Max retries exceeded with url: /definition/english/conversation (Caused by ConnectTimeoutError(<urllib3.connection.HTTPSConnection object at 0x110f6c820>, 'Connection to 62.210.69.176 timed out. (connect timeout=7)')) at 289 - check_search - /Users/truongthuan/Develop/python/blog/flashcard/search.py
 2021-03-27 13:29:57.595586 : HTTPSConnectionPool(host='www.oxfordlearnersdictionaries.com', port=443): Max retries exceeded with url: /definition/english/conversation (Caused by ProxyError('Cannot connect to proxy.', timeout('timed out'))) at 289 - check_search - /Users/truongthuan/Develop/python/blog/flashcard/search.py
 2021-03-27 13:30:04.694015 : HTTPSConnectionPool(host='www.oxfordlearnersdictionaries.com', port=443): Max retries exceeded with url: /definition/english/conversation (Caused by ProxyError('Cannot connect to proxy.', timeout('timed out'))) at 289 - check_search - /Users/truongthuan/Develop/python/blog/flashcard/search.py
 2021-03-27 13:30:12.030516 : HTTPSConnectionPool(host='www.oxfordlearnersdictionaries.com', port=443): Max retries exceeded with url: /definition/english/conversation (Caused by ProxyError('Cannot connect to proxy.', timeout('timed out'))) at 289 - check_search - /Users/truongthuan/Develop/python/blog/flashcard/search.py
 2021-03-27 13:30:15.783162 : HTTPSConnectionPool(host='www.oxfordlearnersdictionaries.com', port=443): Max retries exceeded with url: /definition/english/conversation (Caused by SSLError(SSLCertVerificationError(1, '[SSL: CERTIFICATE_VERIFY_FAILED] certificate verify failed: self signed certificate in certificate chain (_ssl.c:1123)'))) at 289 - check_search - /Users/truongthuan/Develop/python/blog/flashcard/search.py
 2021-03-27 13:30:22.792710 : HTTPSConnectionPool(host='www.oxfordlearnersdictionaries.com', port=443): Max retries exceeded with url: /definition/english/conversation (Caused by ConnectTimeoutError(<urllib3.connection.HTTPSConnection object at 0x11104a2b0>, 'Connection to 191.242.178.209 timed out. (connect timeout=7)')) at 289 - check_search - /Users/truongthuan/Develop/python/blog/flashcard/search.py
 2021-03-27 13:30:30.983010 : saved file conversation+noun+us.mp3 at 58 - downloadFileFromUrl - /Users/truongthuan/Develop/python/blog/flashcard/helper.py
 2021-03-27 13:30:34.932388 : saved file conversation+noun+uk.mp3 at 58 - downloadFileFromUrl - /Users/truongthuan/Develop/python/blog/flashcard/helper.py
 2021-03-27 13:30:34.937150 : Saved <VocabularyCard: conversation > successfully. at 226 - searchVocabulary - /Users/truongthuan/Develop/python/blog/flashcard/search.py
 2021-03-27 13:30:34.937410 : Searching vocabulary <<examine>> at 333 - read_vocabulary_to_search - /Users/truongthuan/Develop/python/blog/flashcard/search.py
 2021-03-27 13:30:41.944358 : HTTPSConnectionPool(host='www.oxfordlearnersdictionaries.com', port=443): Max retries exceeded with url: /definition/english/examine (Caused by ConnectTimeoutError(<urllib3.connection.HTTPSConnection object at 0x111149370>, 'Connection to 192.46.228.240 timed out. (connect timeout=7)')) at 289 - check_search - /Users/truongthuan/Develop/python/blog/flashcard/search.py
 2021-03-27 13:30:42.405006 : HTTPSConnectionPool(host='www.oxfordlearnersdictionaries.com', port=443): Max retries exceeded with url: /definition/english/examine (Caused by ProxyError('Cannot connect to proxy.', NewConnectionError('<urllib3.connection.HTTPSConnection object at 0x1111498e0>: Failed to establish a new connection: [Errno 61] Connection refused'))) at 289 - check_search - /Users/truongthuan/Develop/python/blog/flashcard/search.py
 2021-03-27 13:30:54.629299 : HTTPSConnectionPool(host='www.oxfordlearnersdictionaries.com', port=443): Max retries exceeded with url: /definition/english/examine (Caused by ProxyError('Cannot connect to proxy.', timeout('timed out'))) at 289 - check_search - /Users/truongthuan/Develop/python/blog/flashcard/search.py
 2021-03-27 13:31:02.005983 : HTTPSConnectionPool(host='www.oxfordlearnersdictionaries.com', port=443): Max retries exceeded with url: /definition/english/examine (Caused by ProxyError('Cannot connect to proxy.', timeout('timed out'))) at 289 - check_search - /Users/truongthuan/Develop/python/blog/flashcard/search.py
 2021-03-27 13:31:09.378982 : HTTPSConnectionPool(host='www.oxfordlearnersdictionaries.com', port=443): Max retries exceeded with url: /definition/english/examine (Caused by ProxyError('Cannot connect to proxy.', timeout('timed out'))) at 289 - check_search - /Users/truongthuan/Develop/python/blog/flashcard/search.py
 2021-03-27 13:31:12.612450 : HTTPSConnectionPool(host='www.oxfordlearnersdictionaries.com', port=443): Max retries exceeded with url: /definition/english/examine (Caused by ProxyError('Cannot connect to proxy.', RemoteDisconnected('Remote end closed connection without response'))) at 289 - check_search - /Users/truongthuan/Develop/python/blog/flashcard/search.py
 2021-03-27 13:31:19.823073 : HTTPSConnectionPool(host='www.oxfordlearnersdictionaries.com', port=443): Max retries exceeded with url: /definition/english/examine (Caused by ProxyError('Cannot connect to proxy.', timeout('timed out'))) at 289 - check_search - /Users/truongthuan/Develop/python/blog/flashcard/search.py
 2021-03-27 13:31:20.090982 : HTTPSConnectionPool(host='www.oxfordlearnersdictionaries.com', port=443): Max retries exceeded with url: /definition/english/examine (Caused by ProxyError('Cannot connect to proxy.', NewConnectionError('<urllib3.connection.HTTPSConnection object at 0x1111532b0>: Failed to establish a new connection: [Errno 61] Connection refused'))) at 289 - check_search - /Users/truongthuan/Develop/python/blog/flashcard/search.py
 2021-03-27 13:31:22.647196 : HTTPSConnectionPool(host='www.oxfordlearnersdictionaries.com', port=443): Max retries exceeded with url: /definition/english/examine (Caused by ProxyError('Cannot connect to proxy.', ConnectionResetError(54, 'Connection reset by peer'))) at 289 - check_search - /Users/truongthuan/Develop/python/blog/flashcard/search.py
 2021-03-27 13:31:36.473998 : saved file examine+verb+us.mp3 at 58 - downloadFileFromUrl - /Users/truongthuan/Develop/python/blog/flashcard/helper.py
 2021-03-27 13:31:43.024069 : error: HTTPSConnectionPool(host='www.oxfordlearnersdictionaries.com', port=443): Max retries exceeded with url: /media/english/uk_pron/e/exa/exami/examine__gb_1.mp3 (Caused by ProxyError('Cannot connect to proxy.', RemoteDisconnected('Remote end closed connection without response'))) at 58 - downloadFileFromUrl - /Users/truongthuan/Develop/python/blog/flashcard/helper.py
 2021-03-27 13:31:49.270333 : error: HTTPSConnectionPool(host='www.oxfordlearnersdictionaries.com', port=443): Max retries exceeded with url: /media/english/uk_pron/e/exa/exami/examine__gb_1.mp3 (Caused by ProxyError('Cannot connect to proxy.', RemoteDisconnected('Remote end closed connection without response'))) at 58 - downloadFileFromUrl - /Users/truongthuan/Develop/python/blog/flashcard/helper.py
 2021-03-27 13:32:08.729941 : saved file examine+verb+uk.mp3 at 58 - downloadFileFromUrl - /Users/truongthuan/Develop/python/blog/flashcard/helper.py
 2021-03-27 13:32:08.733746 : Saved <VocabularyCard: examine > successfully. at 226 - searchVocabulary - /Users/truongthuan/Develop/python/blog/flashcard/search.py
 2021-03-27 15:07:23.341322 : error: Got AttributeError when attempting to get a value for field `name` on serializer `TopicSerializer`.
The serializer field might be named incorrectly and not match any attribute or key on the `QuerySet` instance.
Original exception text was: 'QuerySet' object has no attribute 'name'. at 27 - get_topic_list - /Users/truongthuan/Develop/python/blog/flashcard/api.py
 2021-03-27 15:08:45.748806 : error: Got AttributeError when attempting to get a value for field `name` on serializer `TopicSerializer`.
The serializer field might be named incorrectly and not match any attribute or key on the `QuerySet` instance.
Original exception text was: 'QuerySet' object has no attribute 'name'. at 27 - get_topic_list - /Users/truongthuan/Develop/python/blog/flashcard/api.py
 2021-03-27 15:08:46.560519 : error: Got AttributeError when attempting to get a value for field `name` on serializer `TopicSerializer`.
The serializer field might be named incorrectly and not match any attribute or key on the `QuerySet` instance.
Original exception text was: 'QuerySet' object has no attribute 'name'. at 27 - get_topic_list - /Users/truongthuan/Develop/python/blog/flashcard/api.py
 2021-03-27 15:09:04.575542 : error: Got AttributeError when attempting to get a value for field `name` on serializer `TopicSerializer`.
The serializer field might be named incorrectly and not match any attribute or key on the `QuerySet` instance.
Original exception text was: 'QuerySet' object has no attribute 'name'. at 27 - get_topic_list - /Users/truongthuan/Develop/python/blog/flashcard/api.py
 2021-03-27 15:09:05.622342 : error: Got AttributeError when attempting to get a value for field `name` on serializer `TopicSerializer`.
The serializer field might be named incorrectly and not match any attribute or key on the `QuerySet` instance.
Original exception text was: 'QuerySet' object has no attribute 'name'. at 27 - get_topic_list - /Users/truongthuan/Develop/python/blog/flashcard/api.py
 2021-03-27 15:09:31.940321 : error: Got AttributeError when attempting to get a value for field `name` on serializer `TopicSerializer`.
The serializer field might be named incorrectly and not match any attribute or key on the `QuerySet` instance.
Original exception text was: 'QuerySet' object has no attribute 'name'. at 27 - get_topic_list - /Users/truongthuan/Develop/python/blog/flashcard/api.py
 2021-03-27 15:09:32.973183 : error: Got AttributeError when attempting to get a value for field `name` on serializer `TopicSerializer`.
The serializer field might be named incorrectly and not match any attribute or key on the `QuerySet` instance.
Original exception text was: 'QuerySet' object has no attribute 'name'. at 27 - get_topic_list - /Users/truongthuan/Develop/python/blog/flashcard/api.py
 2021-03-27 15:10:19.114787 : error: column flashcard_topic.created_at does not exist
LINE 1: ...hcard_topic"."image", "flashcard_topic"."status", "flashcard...
                                                             ^
 at 27 - get_topic_list - /Users/truongthuan/Develop/python/blog/flashcard/api.py
 2021-03-27 15:26:53.325339 : error: Got AttributeError when attempting to get a value for field `name` on serializer `TopicSerializer`.
The serializer field might be named incorrectly and not match any attribute or key on the `QuerySet` instance.
Original exception text was: 'QuerySet' object has no attribute 'name'. at 27 - get_topic_list - /Users/truongthuan/Develop/python/blog/flashcard/api.py
 2021-03-27 15:26:54.319149 : error: Got AttributeError when attempting to get a value for field `name` on serializer `TopicSerializer`.
The serializer field might be named incorrectly and not match any attribute or key on the `QuerySet` instance.
Original exception text was: 'QuerySet' object has no attribute 'name'. at 27 - get_topic_list - /Users/truongthuan/Develop/python/blog/flashcard/api.py
 2021-03-27 15:35:50.531600 : error: Cannot resolve keyword 'topics_id' into field. Choices are: created_at, definition, example, id, meaning, name, phon_uk, phon_us, sound_uk, sound_us, status, topics, updated_at, word_type at 50 - get_topic_vocabulary - /Users/truongthuan/Develop/python/blog/flashcard/api.py
 2021-03-27 15:35:51.662884 : error: Cannot resolve keyword 'topics_id' into field. Choices are: created_at, definition, example, id, meaning, name, phon_uk, phon_us, sound_uk, sound_us, status, topics, updated_at, word_type at 50 - get_topic_vocabulary - /Users/truongthuan/Develop/python/blog/flashcard/api.py
 2021-03-27 15:36:01.396224 : error: Cannot resolve keyword 'topic_id' into field. Choices are: created_at, definition, example, id, meaning, name, phon_uk, phon_us, sound_uk, sound_us, status, topics, updated_at, word_type at 50 - get_topic_vocabulary - /Users/truongthuan/Develop/python/blog/flashcard/api.py
 2021-03-27 15:36:02.191537 : error: Cannot resolve keyword 'topic_id' into field. Choices are: created_at, definition, example, id, meaning, name, phon_uk, phon_us, sound_uk, sound_us, status, topics, updated_at, word_type at 50 - get_topic_vocabulary - /Users/truongthuan/Develop/python/blog/flashcard/api.py
 2021-03-27 15:37:05.115611 : Searching vocabulary <<conduct>> at 333 - read_vocabulary_to_search - /Users/truongthuan/Develop/python/blog/flashcard/search.py
 2021-03-27 15:37:15.282820 : HTTPSConnectionPool(host='www.oxfordlearnersdictionaries.com', port=443): Max retries exceeded with url: /definition/english/conduct (Caused by ConnectTimeoutError(<urllib3.connection.HTTPSConnection object at 0x104b082e0>, 'Connection to 208.80.28.208 timed out. (connect timeout=7)')) at 289 - check_search - /Users/truongthuan/Develop/python/blog/flashcard/search.py
 2021-03-27 15:37:17.317367 : HTTPSConnectionPool(host='www.oxfordlearnersdictionaries.com', port=443): Max retries exceeded with url: /definition/english/conduct (Caused by ProxyError('Cannot connect to proxy.', NewConnectionError('<urllib3.connection.HTTPSConnection object at 0x104b08a60>: Failed to establish a new connection: [Errno 61] Connection refused'))) at 289 - check_search - /Users/truongthuan/Develop/python/blog/flashcard/search.py
 2021-03-27 15:37:24.324036 : HTTPSConnectionPool(host='www.oxfordlearnersdictionaries.com', port=443): Max retries exceeded with url: /definition/english/conduct (Caused by ConnectTimeoutError(<urllib3.connection.HTTPSConnection object at 0x104b2b2b0>, 'Connection to 178.112.5.135 timed out. (connect timeout=7)')) at 289 - check_search - /Users/truongthuan/Develop/python/blog/flashcard/search.py
 2021-03-27 15:37:25.048621 : HTTPSConnectionPool(host='www.oxfordlearnersdictionaries.com', port=443): Max retries exceeded with url: /definition/english/conduct (Caused by ProxyError('Cannot connect to proxy.', RemoteDisconnected('Remote end closed connection without response'))) at 289 - check_search - /Users/truongthuan/Develop/python/blog/flashcard/search.py
 2021-03-27 15:37:32.056011 : HTTPSConnectionPool(host='www.oxfordlearnersdictionaries.com', port=443): Max retries exceeded with url: /definition/english/conduct (Caused by ConnectTimeoutError(<urllib3.connection.HTTPSConnection object at 0x104b08ac0>, 'Connection to 208.80.28.208 timed out. (connect timeout=7)')) at 289 - check_search - /Users/truongthuan/Develop/python/blog/flashcard/search.py
 2021-03-27 15:37:39.066641 : HTTPSConnectionPool(host='www.oxfordlearnersdictionaries.com', port=443): Max retries exceeded with url: /definition/english/conduct (Caused by ConnectTimeoutError(<urllib3.connection.HTTPSConnection object at 0x104af7730>, 'Connection to 149.125.150.250 timed out. (connect timeout=7)')) at 289 - check_search - /Users/truongthuan/Develop/python/blog/flashcard/search.py
 2021-03-27 15:38:00.153283 : error: HTTPSConnectionPool(host='www.oxfordlearnersdictionaries.com', port=443): Max retries exceeded with url: /media/english/us_pron/x/xco/xcond/xconduct__us_1.mp3 (Caused by ProxyError('Cannot connect to proxy.', RemoteDisconnected('Remote end closed connection without response'))) at 58 - downloadFileFromUrl - /Users/truongthuan/Develop/python/blog/flashcard/helper.py
 2021-03-27 15:38:09.983516 : error: HTTPSConnectionPool(host='www.oxfordlearnersdictionaries.com', port=443): Max retries exceeded with url: /media/english/us_pron/x/xco/xcond/xconduct__us_1.mp3 (Caused by ProxyError('Cannot connect to proxy.', RemoteDisconnected('Remote end closed connection without response'))) at 58 - downloadFileFromUrl - /Users/truongthuan/Develop/python/blog/flashcard/helper.py
 2021-03-27 15:38:28.316289 : error: HTTPSConnectionPool(host='www.oxfordlearnersdictionaries.com', port=443): Max retries exceeded with url: /media/english/us_pron/x/xco/xcond/xconduct__us_1.mp3 (Caused by ProxyError('Cannot connect to proxy.', timeout('timed out'))) at 58 - downloadFileFromUrl - /Users/truongthuan/Develop/python/blog/flashcard/helper.py
 2021-03-27 15:38:52.480657 : saved file conduct+verb+us.mp3 at 58 - downloadFileFromUrl - /Users/truongthuan/Develop/python/blog/flashcard/helper.py
 2021-03-27 15:38:55.955291 : error: HTTPSConnectionPool(host='www.oxfordlearnersdictionaries.com', port=443): Max retries exceeded with url: /media/english/uk_pron/x/xco/xcond/xconduct__gb_4.mp3 (Caused by ProxyError('Cannot connect to proxy.', OSError('Tunnel connection failed: 503 Too many open connections'))) at 58 - downloadFileFromUrl - /Users/truongthuan/Develop/python/blog/flashcard/helper.py
 2021-03-27 15:39:00.690907 : error: HTTPSConnectionPool(host='www.oxfordlearnersdictionaries.com', port=443): Max retries exceeded with url: /media/english/uk_pron/x/xco/xcond/xconduct__gb_4.mp3 (Caused by ProxyError('Cannot connect to proxy.', RemoteDisconnected('Remote end closed connection without response'))) at 58 - downloadFileFromUrl - /Users/truongthuan/Develop/python/blog/flashcard/helper.py
 2021-03-27 15:39:15.823042 : saved file conduct+verb+uk.mp3 at 58 - downloadFileFromUrl - /Users/truongthuan/Develop/python/blog/flashcard/helper.py
 2021-03-27 15:39:15.841635 : Saved <VocabularyCard: conduct > successfully. at 226 - searchVocabulary - /Users/truongthuan/Develop/python/blog/flashcard/search.py
 2021-03-27 15:39:15.841981 : Searching vocabulary <<announce>> at 333 - read_vocabulary_to_search - /Users/truongthuan/Develop/python/blog/flashcard/search.py
 2021-03-27 15:39:22.865444 : HTTPSConnectionPool(host='www.oxfordlearnersdictionaries.com', port=443): Max retries exceeded with url: /definition/english/announce (Caused by ConnectTimeoutError(<urllib3.connection.HTTPSConnection object at 0x104cf2070>, 'Connection to 149.125.150.250 timed out. (connect timeout=7)')) at 289 - check_search - /Users/truongthuan/Develop/python/blog/flashcard/search.py
 2021-03-27 15:39:23.397917 : HTTPSConnectionPool(host='www.oxfordlearnersdictionaries.com', port=443): Max retries exceeded with url: /definition/english/announce (Caused by ProxyError('Cannot connect to proxy.', NewConnectionError('<urllib3.connection.HTTPSConnection object at 0x104cf2820>: Failed to establish a new connection: [Errno 61] Connection refused'))) at 289 - check_search - /Users/truongthuan/Develop/python/blog/flashcard/search.py
 2021-03-27 15:39:24.011568 : HTTPSConnectionPool(host='www.oxfordlearnersdictionaries.com', port=443): Max retries exceeded with url: /definition/english/announce (Caused by ProxyError('Cannot connect to proxy.', RemoteDisconnected('Remote end closed connection without response'))) at 289 - check_search - /Users/truongthuan/Develop/python/blog/flashcard/search.py
 2021-03-27 15:39:24.358328 : HTTPSConnectionPool(host='www.oxfordlearnersdictionaries.com', port=443): Max retries exceeded with url: /definition/english/announce (Caused by ProxyError('Cannot connect to proxy.', NewConnectionError('<urllib3.connection.HTTPSConnection object at 0x104cf2970>: Failed to establish a new connection: [Errno 61] Connection refused'))) at 289 - check_search - /Users/truongthuan/Develop/python/blog/flashcard/search.py
 2021-03-27 15:39:31.366994 : HTTPSConnectionPool(host='www.oxfordlearnersdictionaries.com', port=443): Max retries exceeded with url: /definition/english/announce (Caused by ConnectTimeoutError(<urllib3.connection.HTTPSConnection object at 0x104cfd040>, 'Connection to 149.125.150.250 timed out. (connect timeout=7)')) at 289 - check_search - /Users/truongthuan/Develop/python/blog/flashcard/search.py
 2021-03-27 15:39:31.792852 : HTTPSConnectionPool(host='www.oxfordlearnersdictionaries.com', port=443): Max retries exceeded with url: /definition/english/announce (Caused by ProxyError('Cannot connect to proxy.', NewConnectionError('<urllib3.connection.HTTPSConnection object at 0x104cfd820>: Failed to establish a new connection: [Errno 61] Connection refused'))) at 289 - check_search - /Users/truongthuan/Develop/python/blog/flashcard/search.py
 2021-03-27 15:39:43.201321 : HTTPSConnectionPool(host='www.oxfordlearnersdictionaries.com', port=443): Max retries exceeded with url: /definition/english/announce (Caused by ProxyError('Cannot connect to proxy.', timeout('timed out'))) at 289 - check_search - /Users/truongthuan/Develop/python/blog/flashcard/search.py
 2021-03-27 15:39:46.845056 : error: HTTPSConnectionPool(host='www.oxfordlearnersdictionaries.com', port=443): Max retries exceeded with url: /media/english/us_pron/a/ann/annou/announce__us_1.mp3 (Caused by ProxyError('Cannot connect to proxy.', OSError('Tunnel connection failed: 500 Internal Server Error'))) at 58 - downloadFileFromUrl - /Users/truongthuan/Develop/python/blog/flashcard/helper.py
 2021-03-27 15:39:48.490457 : error: HTTPSConnectionPool(host='www.oxfordlearnersdictionaries.com', port=443): Max retries exceeded with url: /media/english/us_pron/a/ann/annou/announce__us_1.mp3 (Caused by ProxyError('Cannot connect to proxy.', OSError('Tunnel connection failed: 500 Internal Server Error'))) at 58 - downloadFileFromUrl - /Users/truongthuan/Develop/python/blog/flashcard/helper.py
 2021-03-27 15:39:49.100851 : error: HTTPSConnectionPool(host='www.oxfordlearnersdictionaries.com', port=443): Max retries exceeded with url: /media/english/us_pron/a/ann/annou/announce__us_1.mp3 (Caused by ProxyError('Cannot connect to proxy.', OSError('Tunnel connection failed: 500 Internal Server Error'))) at 58 - downloadFileFromUrl - /Users/truongthuan/Develop/python/blog/flashcard/helper.py
 2021-03-27 15:39:50.548800 : error: HTTPSConnectionPool(host='www.oxfordlearnersdictionaries.com', port=443): Max retries exceeded with url: /media/english/us_pron/a/ann/annou/announce__us_1.mp3 (Caused by ProxyError('Cannot connect to proxy.', OSError('Tunnel connection failed: 500 Internal Server Error'))) at 58 - downloadFileFromUrl - /Users/truongthuan/Develop/python/blog/flashcard/helper.py
 2021-03-27 15:39:51.986864 : saved file announce+verb+us.mp3 at 58 - downloadFileFromUrl - /Users/truongthuan/Develop/python/blog/flashcard/helper.py
 2021-03-27 15:39:53.300857 : saved file announce+verb+uk.mp3 at 58 - downloadFileFromUrl - /Users/truongthuan/Develop/python/blog/flashcard/helper.py
 2021-03-27 15:39:53.305580 : Saved <VocabularyCard: announce > successfully. at 226 - searchVocabulary - /Users/truongthuan/Develop/python/blog/flashcard/search.py
 2021-03-27 15:39:53.306010 : Searching vocabulary <<conversation>> at 333 - read_vocabulary_to_search - /Users/truongthuan/Develop/python/blog/flashcard/search.py
 2021-03-27 15:39:54.013371 : HTTPSConnectionPool(host='www.oxfordlearnersdictionaries.com', port=443): Max retries exceeded with url: /definition/english/conversation (Caused by ProxyError('Cannot connect to proxy.', OSError('Tunnel connection failed: 503 Too many open connections'))) at 289 - check_search - /Users/truongthuan/Develop/python/blog/flashcard/search.py
 2021-03-27 15:40:03.107755 : HTTPSConnectionPool(host='www.oxfordlearnersdictionaries.com', port=443): Max retries exceeded with url: /definition/english/conversation (Caused by ProxyError('Cannot connect to proxy.', timeout('timed out'))) at 289 - check_search - /Users/truongthuan/Develop/python/blog/flashcard/search.py
 2021-03-27 15:40:10.118629 : HTTPSConnectionPool(host='www.oxfordlearnersdictionaries.com', port=443): Max retries exceeded with url: /definition/english/conversation (Caused by ConnectTimeoutError(<urllib3.connection.HTTPSConnection object at 0x104e003a0>, 'Connection to 149.125.150.250 timed out. (connect timeout=7)')) at 289 - check_search - /Users/truongthuan/Develop/python/blog/flashcard/search.py
 2021-03-27 15:40:11.521669 : HTTPSConnectionPool(host='www.oxfordlearnersdictionaries.com', port=443): Max retries exceeded with url: /definition/english/conversation (Caused by ProxyError('Cannot connect to proxy.', NewConnectionError('<urllib3.connection.HTTPSConnection object at 0x104cfdac0>: Failed to establish a new connection: [Errno 61] Connection refused'))) at 289 - check_search - /Users/truongthuan/Develop/python/blog/flashcard/search.py
 2021-03-27 15:40:19.616379 : HTTPSConnectionPool(host='www.oxfordlearnersdictionaries.com', port=443): Max retries exceeded with url: /definition/english/conversation (Caused by ProxyError('Cannot connect to proxy.', timeout('timed out'))) at 289 - check_search - /Users/truongthuan/Develop/python/blog/flashcard/search.py
 2021-03-27 15:40:19.919774 : HTTPSConnectionPool(host='www.oxfordlearnersdictionaries.com', port=443): Max retries exceeded with url: /definition/english/conversation (Caused by ProxyError('Cannot connect to proxy.', NewConnectionError('<urllib3.connection.HTTPSConnection object at 0x104e00af0>: Failed to establish a new connection: [Errno 61] Connection refused'))) at 289 - check_search - /Users/truongthuan/Develop/python/blog/flashcard/search.py
 2021-03-27 15:40:20.146352 : HTTPSConnectionPool(host='www.oxfordlearnersdictionaries.com', port=443): Max retries exceeded with url: /definition/english/conversation (Caused by ProxyError('Cannot connect to proxy.', NewConnectionError('<urllib3.connection.HTTPSConnection object at 0x104e0a220>: Failed to establish a new connection: [Errno 61] Connection refused'))) at 289 - check_search - /Users/truongthuan/Develop/python/blog/flashcard/search.py
 2021-03-27 15:40:27.151747 : HTTPSConnectionPool(host='www.oxfordlearnersdictionaries.com', port=443): Max retries exceeded with url: /definition/english/conversation (Caused by ConnectTimeoutError(<urllib3.connection.HTTPSConnection object at 0x104e0aa00>, 'Connection to 178.112.5.135 timed out. (connect timeout=7)')) at 289 - check_search - /Users/truongthuan/Develop/python/blog/flashcard/search.py
 2021-03-27 15:40:29.201881 : HTTPSConnectionPool(host='www.oxfordlearnersdictionaries.com', port=443): Max retries exceeded with url: /definition/english/conversation (Caused by ProxyError('Cannot connect to proxy.', RemoteDisconnected('Remote end closed connection without response'))) at 289 - check_search - /Users/truongthuan/Develop/python/blog/flashcard/search.py
 2021-03-27 15:40:41.266872 : saved file conversation+noun+us.mp3 at 58 - downloadFileFromUrl - /Users/truongthuan/Develop/python/blog/flashcard/helper.py
 2021-03-27 15:40:48.625702 : saved file conversation+noun+uk.mp3 at 58 - downloadFileFromUrl - /Users/truongthuan/Develop/python/blog/flashcard/helper.py
 2021-03-27 15:40:48.630152 : Saved <VocabularyCard: conversation > successfully. at 226 - searchVocabulary - /Users/truongthuan/Develop/python/blog/flashcard/search.py
 2021-03-27 15:40:48.630559 : Searching vocabulary <<examine>> at 333 - read_vocabulary_to_search - /Users/truongthuan/Develop/python/blog/flashcard/search.py
 2021-03-27 15:40:55.639740 : HTTPSConnectionPool(host='www.oxfordlearnersdictionaries.com', port=443): Max retries exceeded with url: /definition/english/examine (Caused by ConnectTimeoutError(<urllib3.connection.HTTPSConnection object at 0x1070e5880>, 'Connection to 191.242.178.209 timed out. (connect timeout=7)')) at 289 - check_search - /Users/truongthuan/Develop/python/blog/flashcard/search.py
 2021-03-27 15:41:02.007870 : saved file examine+verb+us.mp3 at 58 - downloadFileFromUrl - /Users/truongthuan/Develop/python/blog/flashcard/helper.py
 2021-03-27 15:41:03.473008 : saved file examine+verb+uk.mp3 at 58 - downloadFileFromUrl - /Users/truongthuan/Develop/python/blog/flashcard/helper.py
 2021-03-27 15:41:03.477247 : Saved <VocabularyCard: examine > successfully. at 226 - searchVocabulary - /Users/truongthuan/Develop/python/blog/flashcard/search.py
 2021-03-27 15:41:44.330131 : error: Cannot resolve keyword 'topic_id' into field. Choices are: created_at, definition, example, id, meaning, name, phon_uk, phon_us, sound_uk, sound_us, status, topics, updated_at, word_type at 50 - get_topic_vocabulary - /Users/truongthuan/Develop/python/blog/flashcard/api.py
 2021-03-27 15:42:10.606612 : error: Cannot resolve keyword 'topics_id' into field. Choices are: created_at, definition, example, id, meaning, name, phon_uk, phon_us, sound_uk, sound_us, status, topics, updated_at, word_type at 50 - get_topic_vocabulary - /Users/truongthuan/Develop/python/blog/flashcard/api.py
 2021-03-27 15:44:00.896236 : Searching vocabulary <<cross>> at 333 - read_vocabulary_to_search - /Users/truongthuan/Develop/python/blog/flashcard/search.py
 2021-03-27 15:44:07.918983 : HTTPSConnectionPool(host='www.oxfordlearnersdictionaries.com', port=443): Max retries exceeded with url: /definition/english/cross (Caused by ConnectTimeoutError(<urllib3.connection.HTTPSConnection object at 0x1091bd250>, 'Connection to 62.210.69.176 timed out. (connect timeout=7)')) at 289 - check_search - /Users/truongthuan/Develop/python/blog/flashcard/search.py
 2021-03-27 15:44:13.406641 : saved file cross+verb+us.mp3 at 58 - downloadFileFromUrl - /Users/truongthuan/Develop/python/blog/flashcard/helper.py
 2021-03-27 15:44:21.789931 : saved file cross+verb+uk.mp3 at 58 - downloadFileFromUrl - /Users/truongthuan/Develop/python/blog/flashcard/helper.py
 2021-03-27 15:44:21.808889 : Saved <VocabularyCard: cross > successfully. at 226 - searchVocabulary - /Users/truongthuan/Develop/python/blog/flashcard/search.py
 2021-03-27 15:44:21.809139 : Searching vocabulary <<influence>> at 333 - read_vocabulary_to_search - /Users/truongthuan/Develop/python/blog/flashcard/search.py
 2021-03-27 15:44:28.817357 : HTTPSConnectionPool(host='www.oxfordlearnersdictionaries.com', port=443): Max retries exceeded with url: /definition/english/influence (Caused by ConnectTimeoutError(<urllib3.connection.HTTPSConnection object at 0x1093e6850>, 'Connection to 192.46.228.240 timed out. (connect timeout=7)')) at 289 - check_search - /Users/truongthuan/Develop/python/blog/flashcard/search.py
 2021-03-27 15:44:30.594752 : HTTPSConnectionPool(host='www.oxfordlearnersdictionaries.com', port=443): Max retries exceeded with url: /definition/english/influence (Caused by ProxyError('Cannot connect to proxy.', ConnectionResetError(54, 'Connection reset by peer'))) at 289 - check_search - /Users/truongthuan/Develop/python/blog/flashcard/search.py
 2021-03-27 15:44:41.292120 : HTTPSConnectionPool(host='www.oxfordlearnersdictionaries.com', port=443): Read timed out. (read timeout=7) at 289 - check_search - /Users/truongthuan/Develop/python/blog/flashcard/search.py
 2021-03-27 15:44:42.577656 : HTTPSConnectionPool(host='www.oxfordlearnersdictionaries.com', port=443): Max retries exceeded with url: /definition/english/influence (Caused by ProxyError('Cannot connect to proxy.', NewConnectionError('<urllib3.connection.HTTPSConnection object at 0x109406dc0>: Failed to establish a new connection: [Errno 61] Connection refused'))) at 289 - check_search - /Users/truongthuan/Develop/python/blog/flashcard/search.py
 2021-03-27 15:44:49.582963 : HTTPSConnectionPool(host='www.oxfordlearnersdictionaries.com', port=443): Max retries exceeded with url: /definition/english/influence (Caused by ConnectTimeoutError(<urllib3.connection.HTTPSConnection object at 0x1093e6550>, 'Connection to 179.53.220.156 timed out. (connect timeout=7)')) at 289 - check_search - /Users/truongthuan/Develop/python/blog/flashcard/search.py
 2021-03-27 15:44:49.948210 : HTTPSConnectionPool(host='www.oxfordlearnersdictionaries.com', port=443): Max retries exceeded with url: /definition/english/influence (Caused by ProxyError('Cannot connect to proxy.', NewConnectionError('<urllib3.connection.HTTPSConnection object at 0x1094065b0>: Failed to establish a new connection: [Errno 61] Connection refused'))) at 289 - check_search - /Users/truongthuan/Develop/python/blog/flashcard/search.py
 2021-03-27 15:44:56.959340 : HTTPSConnectionPool(host='www.oxfordlearnersdictionaries.com', port=443): Max retries exceeded with url: /definition/english/influence (Caused by ConnectTimeoutError(<urllib3.connection.HTTPSConnection object at 0x109410130>, 'Connection to 45.231.75.35 timed out. (connect timeout=7)')) at 289 - check_search - /Users/truongthuan/Develop/python/blog/flashcard/search.py
 2021-03-27 15:45:00.296790 : HTTPSConnectionPool(host='www.oxfordlearnersdictionaries.com', port=443): Max retries exceeded with url: /definition/english/influence (Caused by ProxyError('Cannot connect to proxy.', NewConnectionError('<urllib3.connection.HTTPSConnection object at 0x109410910>: Failed to establish a new connection: [Errno 61] Connection refused'))) at 289 - check_search - /Users/truongthuan/Develop/python/blog/flashcard/search.py
 2021-03-27 15:45:30.704076 : saved file influence+noun+us.mp3 at 58 - downloadFileFromUrl - /Users/truongthuan/Develop/python/blog/flashcard/helper.py
 2021-03-27 15:45:33.695731 : error: HTTPSConnectionPool(host='www.oxfordlearnersdictionaries.com', port=443): Max retries exceeded with url: /media/english/uk_pron/i/inf/influ/influence__gb_1.mp3 (Caused by ProxyError('Cannot connect to proxy.', RemoteDisconnected('Remote end closed connection without response'))) at 58 - downloadFileFromUrl - /Users/truongthuan/Develop/python/blog/flashcard/helper.py
 2021-03-27 15:45:40.945956 : saved file influence+noun+uk.mp3 at 58 - downloadFileFromUrl - /Users/truongthuan/Develop/python/blog/flashcard/helper.py
 2021-03-27 15:45:40.950493 : Saved <VocabularyCard: influence > successfully. at 226 - searchVocabulary - /Users/truongthuan/Develop/python/blog/flashcard/search.py
 2021-03-27 15:45:40.950699 : Searching vocabulary <<anyway>> at 333 - read_vocabulary_to_search - /Users/truongthuan/Develop/python/blog/flashcard/search.py
 2021-03-27 15:45:46.066522 : saved file anyway+adverb+us.mp3 at 58 - downloadFileFromUrl - /Users/truongthuan/Develop/python/blog/flashcard/helper.py
 2021-03-27 15:45:46.405636 : error: HTTPSConnectionPool(host='www.oxfordlearnersdictionaries.com', port=443): Max retries exceeded with url: /media/english/uk_pron/a/any/anywa/anyway__gb_1.mp3 (Caused by ProxyError('Cannot connect to proxy.', OSError('Tunnel connection failed: 500 Internal Server Error'))) at 58 - downloadFileFromUrl - /Users/truongthuan/Develop/python/blog/flashcard/helper.py
 2021-03-27 15:45:47.801578 : error: HTTPSConnectionPool(host='www.oxfordlearnersdictionaries.com', port=443): Max retries exceeded with url: /media/english/uk_pron/a/any/anywa/anyway__gb_1.mp3 (Caused by ProxyError('Cannot connect to proxy.', OSError('Tunnel connection failed: 500 Internal Server Error'))) at 58 - downloadFileFromUrl - /Users/truongthuan/Develop/python/blog/flashcard/helper.py
 2021-03-27 15:45:50.178990 : saved file anyway+adverb+uk.mp3 at 58 - downloadFileFromUrl - /Users/truongthuan/Develop/python/blog/flashcard/helper.py
 2021-03-27 15:45:50.197782 : Saved <VocabularyCard: anyway > successfully. at 226 - searchVocabulary - /Users/truongthuan/Develop/python/blog/flashcard/search.py
 2021-03-27 15:45:50.198010 : Searching vocabulary <<threaten>> at 333 - read_vocabulary_to_search - /Users/truongthuan/Develop/python/blog/flashcard/search.py
 2021-03-27 15:45:52.320274 : HTTPSConnectionPool(host='www.oxfordlearnersdictionaries.com', port=443): Max retries exceeded with url: /definition/english/threaten (Caused by ProxyError('Cannot connect to proxy.', NewConnectionError('<urllib3.connection.HTTPSConnection object at 0x1095a78e0>: Failed to establish a new connection: [Errno 61] Connection refused'))) at 289 - check_search - /Users/truongthuan/Develop/python/blog/flashcard/search.py
 2021-03-27 15:45:59.785831 : saved file threaten+verb+us.mp3 at 58 - downloadFileFromUrl - /Users/truongthuan/Develop/python/blog/flashcard/helper.py
 2021-03-27 15:46:02.042320 : saved file threaten+verb+uk.mp3 at 58 - downloadFileFromUrl - /Users/truongthuan/Develop/python/blog/flashcard/helper.py
 2021-03-27 15:46:02.046233 : Saved <VocabularyCard: threaten > successfully. at 226 - searchVocabulary - /Users/truongthuan/Develop/python/blog/flashcard/search.py
 2021-03-27 15:46:02.046608 : Searching vocabulary <<commit>> at 333 - read_vocabulary_to_search - /Users/truongthuan/Develop/python/blog/flashcard/search.py
 2021-03-27 15:46:13.759151 : saved file commit+verb+us.mp3 at 58 - downloadFileFromUrl - /Users/truongthuan/Develop/python/blog/flashcard/helper.py
 2021-03-27 15:46:19.450477 : saved file commit+verb+uk.mp3 at 58 - downloadFileFromUrl - /Users/truongthuan/Develop/python/blog/flashcard/helper.py
 2021-03-27 15:46:19.454851 : Saved <VocabularyCard: commit > successfully. at 226 - searchVocabulary - /Users/truongthuan/Develop/python/blog/flashcard/search.py
 2021-03-27 15:46:19.455209 : Searching vocabulary <<female>> at 333 - read_vocabulary_to_search - /Users/truongthuan/Develop/python/blog/flashcard/search.py
 2021-03-27 15:46:28.798801 : HTTPSConnectionPool(host='www.oxfordlearnersdictionaries.com', port=443): Max retries exceeded with url: /definition/english/female (Caused by ProxyError('Cannot connect to proxy.', timeout('timed out'))) at 289 - check_search - /Users/truongthuan/Develop/python/blog/flashcard/search.py
 2021-03-27 15:46:29.378692 : HTTPSConnectionPool(host='www.oxfordlearnersdictionaries.com', port=443): Max retries exceeded with url: /definition/english/female (Caused by ProxyError('Cannot connect to proxy.', OSError('Tunnel connection failed: 503 Too many open connections'))) at 289 - check_search - /Users/truongthuan/Develop/python/blog/flashcard/search.py
 2021-03-27 15:46:32.041561 : HTTPSConnectionPool(host='www.oxfordlearnersdictionaries.com', port=443): Max retries exceeded with url: /definition/english/female (Caused by SSLError(SSLCertVerificationError(1, '[SSL: CERTIFICATE_VERIFY_FAILED] certificate verify failed: self signed certificate in certificate chain (_ssl.c:1123)'))) at 289 - check_search - /Users/truongthuan/Develop/python/blog/flashcard/search.py
 2021-03-27 15:46:39.053908 : HTTPSConnectionPool(host='www.oxfordlearnersdictionaries.com', port=443): Max retries exceeded with url: /definition/english/female (Caused by ConnectTimeoutError(<urllib3.connection.HTTPSConnection object at 0x109706f40>, 'Connection to 192.46.228.240 timed out. (connect timeout=7)')) at 289 - check_search - /Users/truongthuan/Develop/python/blog/flashcard/search.py
 2021-03-27 15:46:46.059322 : HTTPSConnectionPool(host='www.oxfordlearnersdictionaries.com', port=443): Max retries exceeded with url: /definition/english/female (Caused by ConnectTimeoutError(<urllib3.connection.HTTPSConnection object at 0x109710430>, 'Connection to 191.242.178.209 timed out. (connect timeout=7)')) at 289 - check_search - /Users/truongthuan/Develop/python/blog/flashcard/search.py
 2021-03-27 15:46:53.080171 : HTTPSConnectionPool(host='www.oxfordlearnersdictionaries.com', port=443): Max retries exceeded with url: /definition/english/female (Caused by ConnectTimeoutError(<urllib3.connection.HTTPSConnection object at 0x109710c10>, 'Connection to 192.46.228.240 timed out. (connect timeout=7)')) at 289 - check_search - /Users/truongthuan/Develop/python/blog/flashcard/search.py
 2021-03-27 15:46:56.102559 : HTTPSConnectionPool(host='www.oxfordlearnersdictionaries.com', port=443): Max retries exceeded with url: /definition/english/female (Caused by SSLError(SSLCertVerificationError(1, '[SSL: CERTIFICATE_VERIFY_FAILED] certificate verify failed: self signed certificate in certificate chain (_ssl.c:1123)'))) at 289 - check_search - /Users/truongthuan/Develop/python/blog/flashcard/search.py
 2021-03-27 15:47:30.178743 : error: HTTPSConnectionPool(host='www.oxfordlearnersdictionaries.com', port=443): Read timed out. (read timeout=17) at 58 - downloadFileFromUrl - /Users/truongthuan/Develop/python/blog/flashcard/helper.py
 2021-03-27 15:47:35.236080 : saved file female+adjective+us.mp3 at 58 - downloadFileFromUrl - /Users/truongthuan/Develop/python/blog/flashcard/helper.py
 2021-03-27 15:47:52.246240 : error: HTTPSConnectionPool(host='www.oxfordlearnersdictionaries.com', port=443): Max retries exceeded with url: /media/english/uk_pron/f/fem/femal/female__gb_1.mp3 (Caused by ConnectTimeoutError(<urllib3.connection.HTTPSConnection object at 0x1097ca760>, 'Connection to 103.227.254.118 timed out. (connect timeout=17)')) at 58 - downloadFileFromUrl - /Users/truongthuan/Develop/python/blog/flashcard/helper.py
 2021-03-27 15:48:12.398643 : error: HTTPSConnectionPool(host='www.oxfordlearnersdictionaries.com', port=443): Max retries exceeded with url: /media/english/uk_pron/f/fem/femal/female__gb_1.mp3 (Caused by ProxyError('Cannot connect to proxy.', timeout('_ssl.c:1106: The handshake operation timed out'))) at 58 - downloadFileFromUrl - /Users/truongthuan/Develop/python/blog/flashcard/helper.py
 2021-03-27 15:48:29.407525 : error: HTTPSConnectionPool(host='www.oxfordlearnersdictionaries.com', port=443): Max retries exceeded with url: /media/english/uk_pron/f/fem/femal/female__gb_1.mp3 (Caused by ConnectTimeoutError(<urllib3.connection.HTTPSConnection object at 0x1097cad60>, 'Connection to 103.227.254.118 timed out. (connect timeout=17)')) at 58 - downloadFileFromUrl - /Users/truongthuan/Develop/python/blog/flashcard/helper.py
 2021-03-27 15:48:46.429747 : error: HTTPSConnectionPool(host='www.oxfordlearnersdictionaries.com', port=443): Max retries exceeded with url: /media/english/uk_pron/f/fem/femal/female__gb_1.mp3 (Caused by ConnectTimeoutError(<urllib3.connection.HTTPSConnection object at 0x1097d5700>, 'Connection to 103.227.254.118 timed out. (connect timeout=17)')) at 58 - downloadFileFromUrl - /Users/truongthuan/Develop/python/blog/flashcard/helper.py
 2021-03-27 15:48:54.152658 : saved file female+adjective+uk.mp3 at 58 - downloadFileFromUrl - /Users/truongthuan/Develop/python/blog/flashcard/helper.py
 2021-03-27 15:48:54.159191 : Saved <VocabularyCard: female > successfully. at 226 - searchVocabulary - /Users/truongthuan/Develop/python/blog/flashcard/search.py
 2021-03-27 15:48:54.159569 : Searching vocabulary <<youth>> at 333 - read_vocabulary_to_search - /Users/truongthuan/Develop/python/blog/flashcard/search.py
 2021-03-27 15:48:54.192642 : HTTPSConnectionPool(host='www.oxfordlearnersdictionaries.com', port=443): Max retries exceeded with url: /definition/english/youth (Caused by ProxyError('Cannot connect to proxy.', NewConnectionError('<urllib3.connection.HTTPSConnection object at 0x1097d5fa0>: Failed to establish a new connection: [Errno 61] Connection refused'))) at 289 - check_search - /Users/truongthuan/Develop/python/blog/flashcard/search.py
 2021-03-27 15:48:54.661939 : HTTPSConnectionPool(host='www.oxfordlearnersdictionaries.com', port=443): Max retries exceeded with url: /definition/english/youth (Caused by ProxyError('Cannot connect to proxy.', NewConnectionError('<urllib3.connection.HTTPSConnection object at 0x1097c1a00>: Failed to establish a new connection: [Errno 61] Connection refused'))) at 289 - check_search - /Users/truongthuan/Develop/python/blog/flashcard/search.py
 2021-03-27 15:48:54.962307 : HTTPSConnectionPool(host='www.oxfordlearnersdictionaries.com', port=443): Max retries exceeded with url: /definition/english/youth (Caused by ProxyError('Cannot connect to proxy.', NewConnectionError('<urllib3.connection.HTTPSConnection object at 0x109710d00>: Failed to establish a new connection: [Errno 61] Connection refused'))) at 289 - check_search - /Users/truongthuan/Develop/python/blog/flashcard/search.py
 2021-03-27 15:49:06.036704 : saved file youth+noun+us.mp3 at 58 - downloadFileFromUrl - /Users/truongthuan/Develop/python/blog/flashcard/helper.py
 2021-03-27 15:49:17.295838 : saved file youth+noun+uk.mp3 at 58 - downloadFileFromUrl - /Users/truongthuan/Develop/python/blog/flashcard/helper.py
 2021-03-27 15:49:17.299507 : Saved <VocabularyCard: youth > successfully. at 226 - searchVocabulary - /Users/truongthuan/Develop/python/blog/flashcard/search.py
 2021-03-27 15:49:17.299764 : Searching vocabulary <<wave>> at 333 - read_vocabulary_to_search - /Users/truongthuan/Develop/python/blog/flashcard/search.py
 2021-03-27 15:49:17.599192 : HTTPSConnectionPool(host='www.oxfordlearnersdictionaries.com', port=443): Max retries exceeded with url: /definition/english/wave (Caused by ProxyError('Cannot connect to proxy.', NewConnectionError('<urllib3.connection.HTTPSConnection object at 0x1097a0220>: Failed to establish a new connection: [Errno 61] Connection refused'))) at 289 - check_search - /Users/truongthuan/Develop/python/blog/flashcard/search.py
 2021-03-27 15:49:25.735370 : HTTPSConnectionPool(host='www.oxfordlearnersdictionaries.com', port=443): Max retries exceeded with url: /definition/english/wave (Caused by ProxyError('Cannot connect to proxy.', timeout('timed out'))) at 289 - check_search - /Users/truongthuan/Develop/python/blog/flashcard/search.py
 2021-03-27 15:49:34.126991 : HTTPSConnectionPool(host='www.oxfordlearnersdictionaries.com', port=443): Max retries exceeded with url: /definition/english/wave (Caused by ProxyError('Cannot connect to proxy.', timeout('timed out'))) at 289 - check_search - /Users/truongthuan/Develop/python/blog/flashcard/search.py
 2021-03-27 15:49:38.083516 : saved file wave+noun+us.mp3 at 58 - downloadFileFromUrl - /Users/truongthuan/Develop/python/blog/flashcard/helper.py
 2021-03-27 15:49:40.026858 : saved file wave+noun+uk.mp3 at 58 - downloadFileFromUrl - /Users/truongthuan/Develop/python/blog/flashcard/helper.py
 2021-03-27 15:49:40.030508 : Saved <VocabularyCard: wave > successfully. at 226 - searchVocabulary - /Users/truongthuan/Develop/python/blog/flashcard/search.py